Workbook

Sheet Ejecutivos
A1: Rut | B1: Nombre completo | C1: Supervisor | D1: Equipo | E1: Cargo | F1: Fecha ingreso | G1: Jornada | H1: Estado | I1: Correo | J1: Teléfono | K1: Observaciones
A2: 26612947-5 | B2: ALEJANDRA CHACON | C2: LUZ GARCIA | D2: Equipo A | E2: Ejecutivo | F2: 45785 | G2: Full time | H2: Activo | I2: ok
A3: 13093458-7 | B3: ALEJANDRA ORELLANA | C3: LUZ GARCIA | D3: Equipo A | E3: Ejecutivo | F3: 45390 | G3: Full time | H3: Activo | I3: ok
A4: 13336644-k | B4: ANA ASTORGA | C4: LUZ GARCIA | D4: Equipo A | E4: Ejecutivo | F4: 18/03/2026 | G4: Full time | H4: Activo | I4: ok
A5: 19060841-7 | B5: ATALY GARCIA | C5: LUZ GARCIA | D5: Equipo A | E5: Ejecutivo | F5: 45819 | G5: Full time | H5: Activo | I5: ok
A6: 18696966-9 | B6: CATHERINE AEDO | C6: LUZ GARCIA | D6: Equipo A | E6: Ejecutivo | F6: 46120 | G6: Full time | H6: Activo | I6: ok
A7: 18637622-6 | B7: DANIELA RODRIGUEZ | C7: LUZ GARCIA | D7: Equipo A | E7: Ejecutivo | F7: 45642 | G7: Full time | H7: Activo
A8: 14364155-4 | B8: ELSA GONGORA | C8: LUZ GARCIA | D8: Equipo A | E8: Ejecutivo | F8: 45229 | G8: Full time | H8: Activo | I8: ok
A9: 16117577-3 | B9: JOHANA LLANCAPICHUN | C9: LUZ GARCIA | D9: Equipo A | E9: Ejecutivo | F9: 45819 | G9: Full time | H9: Activo | I9: ok
A10: 13026344-5 | B10: KATIA HALD | C10: LUZ GARCIA | D10: Equipo A | E10: Ejecutivo | F10: 45355 | G10: Full time | H10: Activo | I10: ok
A11: 13638765-0 | B11: MANUEL MONSALVE | C11: LUZ GARCIA | D11: Equipo A | E11: Ejecutivo | F11: 45558 | G11: Full time | H11: Activo | I11: ok
A12: 13337549-K | B12: MANUELA ASTUDILLO | C12: LUZ GARCIA | D12: Equipo A | E12: Ejecutivo | F12: 45819 | G12: Full time | H12: Activo
A13: 10446967-1 | B13: MARIA LORETO VELASQUEZ | C13: LUZ GARCIA | D13: Equipo A | E13: Ejecutivo | F13: 16/11/2021 | G13: Full time | H13: Activo
A14: 18123009-6 | B14: MAXIMILIANO OLIVARES | C14: LUZ GARCIA | D14: Equipo A | E14: Ejecutivo | F14: 45455 | G14: Full time | H14: Activo | I14: ok
A15: 19421111-2 | B15: MELISSA SALGADO | C15: LUZ GARCIA | D15: Equipo A | E15: Ejecutivo | F15: 45819 | G15: Full time | H15: Activo | I15: ok
A16: 27105214-6 | B16: NANCI MENDEZ | C16: LUZ GARCIA | D16: Equipo A | E16: Ejecutivo | F16: 27/05/2025 | G16: Full time | H16: Activo | I16: ok
A17: 20828148-8 | B17: TOMAS MAULEN | C17: LUZ GARCIA | D17: Equipo A | E17: Ejecutivo | F17: 46120 | G17: Full time | H17: Activo | I17: ok

Sheet Turno
A1: N° | B1: Nombre | C1: 3 | D1: 4 | E1: 5 | F1: 6 | G1: 7 | H1: 10 | I1: 11 | J1: 12 | K1: 13 | L1: 14 | M1: 17 | N1: 18 | O1: 19 | P1: 20 | Q1: 21 | R1: 24 | S1: 25 | T1: 26 | U1: 27 | V1: 28
C2: L | D2: M | E2: MI | F2: J | G2: V | H2: L | I2: M | J2: MI | K2: J | L2: V | M2: L | N2: M | O2: MI | P2: J | Q2: V | R2: L | S2: M | T2: MI | U2: J | V2: V
A3: 1 | B3: =IFERROR(INDEX(Ejecutivos!$B$2:$B$100,1),"") -> ALEJANDRA CHACON | C3: A | D3: A | E3: A | F3: B | G3: C | H3: A | I3: A | J3: D | K3: C | L3: A | M3: C | N3: A | O3: A | P3: A | Q3: B | R3: A | S3: B | T3: C | U3: A | V3: A
A4: 2 | B4: =IFERROR(INDEX(Ejecutivos!$B$2:$B$100,2),"") -> ALEJANDRA ORELLANA | C4: A | D4: D | E4: A | F4: A | G4: C | H4: A | I4: C | J4: B | K4: A | L4: A | M4: A | N4: A | O4: A | P4: C | Q4: B | R4: A | S4: C | T4: A | U4: D | V4: A
A5: 3 | B5: =IFERROR(INDEX(Ejecutivos!$B$2:$B$100,3),"") -> ANA ASTORGA | C5: A | D5: C | E5: B | F5: A | G5: A | H5: A | I5: A | J5: A | K5: B | L5: V | M5: C | N5: A | O5: A | P5: A | Q5: D | R5: B | S5: A | T5: A | U5: C | V5: A
A6: 4 | B6: =IFERROR(INDEX(Ejecutivos!$B$2:$B$100,4),"") -> ATALY GARCIA | C6: A | D6: C | E6: A | F6: D | G6: A | H6: B | I6: A | J6: A | K6: A | L6: C | M6: A | N6: C | O6: B | P6: A | Q6: A | R6: A | S6: A | T6: A | U6: C | V6: B
A7: 5 | B7: =IFERROR(INDEX(Ejecutivos!$B$2:$B$100,5),"") -> CATHERINE AEDO | C7: A | D7: C | E7: B | F7: A | G7: A | H7: A | I7: A | J7: A | K7: C | L7: B | M7: A | N7: C | O7: A | P7: D | Q7: A | R7: B | S7: A | T7: A | U7: A | V7: C
A8: 6 | B8: =IFERROR(INDEX(Ejecutivos!$B$2:$B$100,6),"") -> DANIELA RODRIGUEZ | C8: C | D8: A | E8: A | F8: A | G8: B | H8: A | I8: B | J8: C | K8: A | L8: A | M8: A | N8: A | O8: A | P8: B | Q8: C | R8: A | S8: A | T8: D | U8: C | V8: A
A9: 7 | B9: =IFERROR(INDEX(Ejecutivos!$B$2:$B$100,7),"") -> ELSA GONGORA | C9: A | D9: A | E9: D | F9: C | G9: A | H9: C | I9: A | J9: A | K9: A | L9: B | M9: A | N9: B | O9: C | P9: A | Q9: A | R9: A | S9: A | T9: A | U9: B | V9: C
A10: 8 | B10: =IFERROR(INDEX(Ejecutivos!$B$2:$B$100,8),"") -> JOHANA LLANCAPICHUN | C10: A | D10: A | E10: A | F10: B | G10: C | H10: A | I10: D | J10: C | K10: A | L10: A | M10: A | N10: A | O10: A | P10: B | Q10: V | R10: A | S10: B | T10: C | U10: A | V10: A
A11: 9 | B11: =IFERROR(INDEX(Ejecutivos!$B$2:$B$100,9),"") -> KATIA HALD | C11: A | D11: A | E11: A | F11: B | G11: C | H11: A | I11: B | J11: C | K11: A | L11: A | M11: A | N11: A | O11: A | P11: B | Q11: C | R11: A | S11: D | T11: C | U11: A | V11: A
A12: 10 | B12: =IFERROR(INDEX(Ejecutivos!$B$2:$B$100,10),"") -> MANUEL MONSALVE | C12: A | D12: A | E12: A | F12: C | G12: B | H12: C | I12: A | J12: A | K12: A | L12: D | M12: B | N12: A | O12: A | P12: C | Q12: A | R12: A | S12: C | T12: B | U12: A | V12: A
A13: 11 | B13: =IFERROR(INDEX(Ejecutivos!$B$2:$B$100,11),"") -> MANUELA ASTUDILLO | C13: A | D13: A | E13: A | F13: C | G13: B | H13: A | I13: C | J13: A | K13: D | L13: A | M13: B | N13: A | O13: A | P13: A | Q13: C | R13: A | S13: C | T13: B | U13: A | V13: A
A14: 12 | B14: =IFERROR(INDEX(Ejecutivos!$B$2:$B$100,12),"") -> MARIA LORETO VELASQUEZ | C14: C | D14: A | E14: A | F14: A | G14: D | H14: B | I14: A | J14: A | K14: C | L14: A | M14: A | N14: C | O14: B | P14: A | Q14: A | R14: A | S14: A | T14: A | U14: C | V14: B
A15: 13 | B15: =IFERROR(INDEX(Ejecutivos!$B$2:$B$100,13),"") -> MAXIMILIANO OLIVARES | C15: C | D15: A | E15: A | F15: A | G15: D | H15: B | I15: A | J15: A | K15: C | L15: A | M15: A | N15: C | O15: B | P15: A | Q15: A | R15: A | S15: A | T15: A | U15: C | V15: B
A16: 14 | B16: =IFERROR(INDEX(Ejecutivos!$B$2:$B$100,14),"") -> MELISSA SALGADO | C16: B | D16: A | E16: A | F16: C | G16: A | H16: A | I16: C | J16: B | K16: A | L16: A | M16: A | N16: A | O16: A | P16: C | Q16: B | R16: C | S16: A | T16: A | U16: A | V16: D
A17: 15 | B17: =IFERROR(INDEX(Ejecutivos!$B$2:$B$100,15),"") -> NANCI MENDEZ | C17: B | D17: A | E17: C | F17: A | G17: A | H17: A | I17: A | J17: A | K17: B | L17: C | M17: A | N17: B | O17: C | P17: A | Q17: A | R17: A | S17: A | T17: A | U17: B | V17: C
A18: 16 | B18: =IFERROR(INDEX(Ejecutivos!$B$2:$B$100,16),"") -> TOMAS MAULEN | C18: A | D18: B | E18: C | F18: A | G18: A | H18: A | I18: A | J18: A | K18: B | L18: C | M18: A | N18: D | O18: C | P18: A | Q18: A | R18: A | S18: A | T18: A | U18: B | V18: C
A19: 17 | B19: =IFERROR(INDEX(Ejecutivos!$B$2:$B$100,17),"") -> 0 | C19: A | D19: B | E19: C | F19: A | G19: A | H19: A | I19: A | J19: A | K19: B | L19: C | M19: A | N19: A | O19: D | P19: C | Q19: A | R19: C | S19: A | T19: A | U19: A | V19: B
A20: 18 | B20: =IFERROR(INDEX(Ejecutivos!$B$2:$B$100,18),"") -> 0
A21: 19 | B21: =IFERROR(INDEX(Ejecutivos!$B$2:$B$100,19),"") -> 0
A22: 20 | B22: =IFERROR(INDEX(Ejecutivos!$B$2:$B$100,20),"") -> 0
A23: 21 | B23: =IFERROR(INDEX(Ejecutivos!$B$2:$B$100,21),"") -> 0
A24: 22 | B24: =IFERROR(INDEX(Ejecutivos!$B$2:$B$100,22),"") -> 0
A25: 23 | B25: =IFERROR(INDEX(Ejecutivos!$B$2:$B$100,23),"") -> 0
A26: 24 | B26: =IFERROR(INDEX(Ejecutivos!$B$2:$B$100,24),"") -> 0
A27: 25 | B27: =IFERROR(INDEX(Ejecutivos!$B$2:$B$100,25),"") -> 0
A28: 26 | B28: =IFERROR(INDEX(Ejecutivos!$B$2:$B$100,26),"") -> 0
A29: 27 | B29: =IFERROR(INDEX(Ejecutivos!$B$2:$B$100,27),"") -> 0
A30: 28 | B30: =IFERROR(INDEX(Ejecutivos!$B$2:$B$100,28),"") -> 0
A31: 29 | B31: =IFERROR(INDEX(Ejecutivos!$B$2:$B$100,29),"") -> 0
A32: 30 | B32: =IFERROR(INDEX(Ejecutivos!$B$2:$B$100,30),"") -> 0

Sheet Config
B2: Parámetros del sistema
B4: Metas de desempeño
B5: Indicador | C5: Meta
B6: Contactabilidad | C6: 0.85
B7: Calidad (puntaje /100) | C7: 95
B8: EPA (ver bloque Metas EPA) | C8: 95
B9: Adherencia | C9: 0.92
B10: TMO meta (segundos) | C10: 300
B13: Turnos
B14: Turno | C14: Hora inicio programada | D14: Hora término programada | E14: Duración colación (min) | F14: Hrs. Netas | G14: Descripción
B15: A | C15: 0.35416667 | D15: 0.77083333 | E15: 60 | F15: 9,0 | G15: Jornada larga mañana
B16: B | C16: 0.35416667 | D16: 0.72916667 | E16: 60 | F16: 8,0 | G16: Jornada estándar mañana
B17: C | C17: 0.35416667 | D17: 0.6875 | E17: 60 | F17: 7,0 | G17: Jornada corta mañana
B18: D | C18: 0.39583333 | D18: 0.77083333 | E18: 60 | F18: 8,0 | G18: Jornada tarde
B20: Metas EPA
B21: Indicador | C21: Meta
B22: EPA 1 SNL | C22: 0.95
B23: EPA 2 SNL | C23: 0.9
B24: EPA 1 EP | C24: 0.95
B25: EPA 2 EP | C25: 0.9
B28: Otras metas
B29: Indicador | C29: Meta
B30: Tipificaciones | C30: 0.95
B31: Outbound - % Contacto | C31: 0.85
B32: Transferencia EPA | C32: 0.85

Sheet Asistencia
A1: Fecha | B1: Rut | C1: Nombre | D1: Hora ingreso | E1: Hora salida | F1: Inicio comida | G1: Fin comida | H1: Descanso 1 (min) | I1: Descanso 2 (min) | J1: Baño | K1: Baño (veces) | L1: Capacitación (min) | M1: Tiempo efectivo (hrs) | N1: Minutos de atraso | O1: Minutos de colación | P1: Tiempo total descanso (min) | Q1: Desviación del turno (min) | R1: Estado | S1: Turno del día | T1: Salida anticipada (min) | U1: Adherencia (%) | V1: Observaciones
A2: 46237 | B2: 26612947-5 | C2: =IFERROR(INDEX(Ejecutivos!$B$2:$B$100,MATCH(B2,Ejecutivos!$A$2:$A$100,0)),"") -> ALEJANDRA CHACON | D2: 08:41 | E2: 18:30 | F2: 14:02 | G2: 15:02 | H2: 17 | I2: 16 | J2: 22 | K2: 3 | L2: 0 | M2: =IF(OR(D2="",E2=""),"",ROUND(((E2-D2)*24)-((G2-F2)*24)-((H2+I2)/60),2)) -> 8.27 | N2: =IF(OR($D2="",$S2=""),"",IFERROR(MAX(0,ROUND(($D2-INDEX(Config!$C$15:$C$18,MATCH($S2,Config!$B$15:$B$18,0)))*24*60,0)),"")) -> 11 | O2: =IF(OR(F2="",G2=""),"",ROUND((G2-F2)*24*60,0)) -> 60 | P2: =IF(O2="","",O2+H2+I2) -> 93 | Q2: =IF(OR($P2="",$S2=""),"",IFERROR($P2-INDEX(Config!$E$15:$E$18,MATCH($S2,Config!$B$15:$B$18,0)),"")) -> 33 | R2: =IF($A2="","",IF($D2="","Ausente",IF($N2="","",IF($N2>0,"Atrasado","Puntual")))) -> Atrasado | S2: =IF(OR($A2="",$C2=""),"",IFERROR(INDEX(Turno!$C$3:$V$32,MATCH($C2,Turno!$B$3:$B$32,0),MATCH(DAY($A2),Turno!$C$1:$V$1,0)),"")) -> A | T2: =IF(OR($E2="",$S2=""),"",IFERROR(MAX(0,ROUND((INDEX(Config!$D$15:$D$18,MATCH($S2,Config!$B$15:$B$18,0))-$E2)*1440,0)),"")) -> 0 | U2: =IF(OR($N2="",$T2=""),"",IFERROR(MAX(0,1-($N2+$T2+MAX(0,N($Q2)))/ROUND((INDEX(Config!$D$15:$D$18,MATCH($S2,Config!$B$15:$B$18,0))-INDEX(Config!$C$15:$C$18,MATCH($S2,Config!$B$15:$B$18,0)))*1440,0)),"")) -> 0.92666667
A3: 46237 | B3: 13093458-7 | C3: =IFERROR(INDEX(Ejecutivos!$B$2:$B$100,MATCH(B3,Ejecutivos!$A$2:$A$100,0)),"") -> ALEJANDRA ORELLANA | D3: 08:30 | E3: 17:30 | F3: 0 | G3: 0 | H3: 15 | I3: 8 | J3: 2 | K3: 1 | L3: 0 | M3: =IF(OR(D3="",E3=""),"",ROUND(((E3-D3)*24)-((G3-F3)*24)-((H3+I3)/60),2)) -> 8.62 | N3: =IF(OR($D3="",$S3=""),"",IFERROR(MAX(0,ROUND(($D3-INDEX(Config!$C$15:$C$18,MATCH($S3,Config!$B$15:$B$18,0)))*24*60,0)),"")) -> 0 | O3: =IF(OR(F3="",G3=""),"",ROUND((G3-F3)*24*60,0)) -> 0 | P3: =IF(O3="","",O3+H3+I3) -> 23 | Q3: =IF(OR($P3="",$S3=""),"",IFERROR($P3-INDEX(Config!$E$15:$E$18,MATCH($S3,Config!$B$15:$B$18,0)),"")) -> -37 | R3: =IF($A3="","",IF($D3="","Ausente",IF($N3="","",IF($N3>0,"Atrasado","Puntual")))) -> Puntual | S3: =IF(OR($A3="",$C3=""),"",IFERROR(INDEX(Turno!$C$3:$V$32,MATCH($C3,Turno!$B$3:$B$32,0),MATCH(DAY($A3),Turno!$C$1:$V$1,0)),"")) -> A | T3: =IF(OR($E3="",$S3=""),"",IFERROR(MAX(0,ROUND((INDEX(Config!$D$15:$D$18,MATCH($S3,Config!$B$15:$B$18,0))-$E3)*1440,0)),"")) -> 60 | U3: =IF(OR($N3="",$T3=""),"",IFERROR(MAX(0,1-($N3+$T3+MAX(0,N($Q3)))/ROUND((INDEX(Config!$D$15:$D$18,MATCH($S3,Config!$B$15:$B$18,0))-INDEX(Config!$C$15:$C$18,MATCH($S3,Config!$B$15:$B$18,0)))*1440,0)),"")) -> 0.9
A4: 46237 | B4: 19060841-7 | C4: =IFERROR(INDEX(Ejecutivos!$B$2:$B$100,MATCH(B4,Ejecutivos!$A$2:$A$100,0)),"") -> ATALY GARCIA | D4: 08:28 | E4: 18:10 | F4: 13:04 | G4: 13:34 | H4: 15 | I4: 15 | J4: 23 | K4: 3 | L4: 0 | M4: =IF(OR(D4="",E4=""),"",ROUND(((E4-D4)*24)-((G4-F4)*24)-((H4+I4)/60),2)) -> 8.7 | N4: =IF(OR($D4="",$S4=""),"",IFERROR(MAX(0,ROUND(($D4-INDEX(Config!$C$15:$C$18,MATCH($S4,Config!$B$15:$B$18,0)))*24*60,0)),"")) -> 0 | O4: =IF(OR(F4="",G4=""),"",ROUND((G4-F4)*24*60,0)) -> 30 | P4: =IF(O4="","",O4+H4+I4) -> 60 | Q4: =IF(OR($P4="",$S4=""),"",IFERROR($P4-INDEX(Config!$E$15:$E$18,MATCH($S4,Config!$B$15:$B$18,0)),"")) -> 0 | R4: =IF($A4="","",IF($D4="","Ausente",IF($N4="","",IF($N4>0,"Atrasado","Puntual")))) -> Puntual | S4: =IF(OR($A4="",$C4=""),"",IFERROR(INDEX(Turno!$C$3:$V$32,MATCH($C4,Turno!$B$3:$B$32,0),MATCH(DAY($A4),Turno!$C$1:$V$1,0)),"")) -> A | T4: =IF(OR($E4="",$S4=""),"",IFERROR(MAX(0,ROUND((INDEX(Config!$D$15:$D$18,MATCH($S4,Config!$B$15:$B$18,0))-$E4)*1440,0)),"")) -> 20 | U4: =IF(OR($N4="",$T4=""),"",IFERROR(MAX(0,1-($N4+$T4+MAX(0,N($Q4)))/ROUND((INDEX(Config!$D$15:$D$18,MATCH($S4,Config!$B$15:$B$18,0))-INDEX(Config!$C$15:$C$18,MATCH($S4,Config!$B$15:$B$18,0)))*1440,0)),"")) -> 0.96666667
A5: 46237 | B5: 18696966-9 | C5: =IFERROR(INDEX(Ejecutivos!$B$2:$B$100,MATCH(B5,Ejecutivos!$A$2:$A$100,0)),"") -> CATHERINE AEDO | D5: 08:10 | E5: 18:39 | F5: 13:44 | G5: 14:47 | H5: 17 | I5: 19 | J5: 41 | K5: 5 | L5: 0 | M5: =IF(OR(D5="",E5=""),"",ROUND(((E5-D5)*24)-((G5-F5)*24)-((H5+I5)/60),2)) -> 8.83 | N5: =IF(OR($D5="",$S5=""),"",IFERROR(MAX(0,ROUND(($D5-INDEX(Config!$C$15:$C$18,MATCH($S5,Config!$B$15:$B$18,0)))*24*60,0)),"")) -> 0 | O5: =IF(OR(F5="",G5=""),"",ROUND((G5-F5)*24*60,0)) -> 63 | P5: =IF(O5="","",O5+H5+I5) -> 99 | Q5: =IF(OR($P5="",$S5=""),"",IFERROR($P5-INDEX(Config!$E$15:$E$18,MATCH($S5,Config!$B$15:$B$18,0)),"")) -> 39 | R5: =IF($A5="","",IF($D5="","Ausente",IF($N5="","",IF($N5>0,"Atrasado","Puntual")))) -> Puntual | S5: =IF(OR($A5="",$C5=""),"",IFERROR(INDEX(Turno!$C$3:$V$32,MATCH($C5,Turno!$B$3:$B$32,0),MATCH(DAY($A5),Turno!$C$1:$V$1,0)),"")) -> A | T5: =IF(OR($E5="",$S5=""),"",IFERROR(MAX(0,ROUND((INDEX(Config!$D$15:$D$18,MATCH($S5,Config!$B$15:$B$18,0))-$E5)*1440,0)),"")) -> 0 | U5: =IF(OR($N5="",$T5=""),"",IFERROR(MAX(0,1-($N5+$T5+MAX(0,N($Q5)))/ROUND((INDEX(Config!$D$15:$D$18,MATCH($S5,Config!$B$15:$B$18,0))-INDEX(Config!$C$15:$C$18,MATCH($S5,Config!$B$15:$B$18,0)))*1440,0)),"")) -> 0.935
A6: 46237 | B6: 18637622-6 | C6: =IFERROR(INDEX(Ejecutivos!$B$2:$B$100,MATCH(B6,Ejecutivos!$A$2:$A$100,0)),"") -> DANIELA RODRIGUEZ | D6: 08:31 | E6: 18:31 | F6: 15:06 | G6: 15:33 | H6: 16 | I6: 16 | J6: 21 | K6: 4 | L6: 0 | M6: =IF(OR(D6="",E6=""),"",ROUND(((E6-D6)*24)-((G6-F6)*24)-((H6+I6)/60),2)) -> 9.02 | N6: =IF(OR($D6="",$S6=""),"",IFERROR(MAX(0,ROUND(($D6-INDEX(Config!$C$15:$C$18,MATCH($S6,Config!$B$15:$B$18,0)))*24*60,0)),"")) -> 1 | O6: =IF(OR(F6="",G6=""),"",ROUND((G6-F6)*24*60,0)) -> 27 | P6: =IF(O6="","",O6+H6+I6) -> 59 | Q6: =IF(OR($P6="",$S6=""),"",IFERROR($P6-INDEX(Config!$E$15:$E$18,MATCH($S6,Config!$B$15:$B$18,0)),"")) -> -1 | R6: =IF($A6="","",IF($D6="","Ausente",IF($N6="","",IF($N6>0,"Atrasado","Puntual")))) -> Atrasado | S6: =IF(OR($A6="",$C6=""),"",IFERROR(INDEX(Turno!$C$3:$V$32,MATCH($C6,Turno!$B$3:$B$32,0),MATCH(DAY($A6),Turno!$C$1:$V$1,0)),"")) -> C | T6: =IF(OR($E6="",$S6=""),"",IFERROR(MAX(0,ROUND((INDEX(Config!$D$15:$D$18,MATCH($S6,Config!$B$15:$B$18,0))-$E6)*1440,0)),"")) -> 0 | U6: =IF(OR($N6="",$T6=""),"",IFERROR(MAX(0,1-($N6+$T6+MAX(0,N($Q6)))/ROUND((INDEX(Config!$D$15:$D$18,MATCH($S6,Config!$B$15:$B$18,0))-INDEX(Config!$C$15:$C$18,MATCH($S6,Config!$B$15:$B$18,0)))*1440,0)),"")) -> 0.99791667
A7: 46237 | B7: 14364155-4 | C7: =IFERROR(INDEX(Ejecutivos!$B$2:$B$100,MATCH(B7,Ejecutivos!$A$2:$A$100,0)),"") -> ELSA GONGORA | D7: 08:30 | E7: 18:31 | F7: 13:05 | G7: 14:05 | H7: 15 | I7: 15 | J7: 11 | K7: 3 | L7: 0 | M7: =IF(OR(D7="",E7=""),"",ROUND(((E7-D7)*24)-((G7-F7)*24)-((H7+I7)/60),2)) -> 8.52 | N7: =IF(OR($D7="",$S7=""),"",IFERROR(MAX(0,ROUND(($D7-INDEX(Config!$C$15:$C$18,MATCH($S7,Config!$B$15:$B$18,0)))*24*60,0)),"")) -> 0 | O7: =IF(OR(F7="",G7=""),"",ROUND((G7-F7)*24*60,0)) -> 60 | P7: =IF(O7="","",O7+H7+I7) -> 90 | Q7: =IF(OR($P7="",$S7=""),"",IFERROR($P7-INDEX(Config!$E$15:$E$18,MATCH($S7,Config!$B$15:$B$18,0)),"")) -> 30 | R7: =IF($A7="","",IF($D7="","Ausente",IF($N7="","",IF($N7>0,"Atrasado","Puntual")))) -> Puntual | S7: =IF(OR($A7="",$C7=""),"",IFERROR(INDEX(Turno!$C$3:$V$32,MATCH($C7,Turno!$B$3:$B$32,0),MATCH(DAY($A7),Turno!$C$1:$V$1,0)),"")) -> A | T7: =IF(OR($E7="",$S7=""),"",IFERROR(MAX(0,ROUND((INDEX(Config!$D$15:$D$18,MATCH($S7,Config!$B$15:$B$18,0))-$E7)*1440,0)),"")) -> 0 | U7: =IF(OR($N7="",$T7=""),"",IFERROR(MAX(0,1-($N7+$T7+MAX(0,N($Q7)))/ROUND((INDEX(Config!$D$15:$D$18,MATCH($S7,Config!$B$15:$B$18,0))-INDEX(Config!$C$15:$C$18,MATCH($S7,Config!$B$15:$B$18,0)))*1440,0)),"")) -> 0.95
A8: 46237 | B8: 16117577-3 | C8: =IFERROR(INDEX(Ejecutivos!$B$2:$B$100,MATCH(B8,Ejecutivos!$A$2:$A$100,0)),"") -> JOHANA LLANCAPICHUN | D8: 08:30 | E8: 18:40 | F8: 14:54 | G8: 15:00 | H8: 15 | I8: 15 | J8: 6 | K8: 1 | L8: 0 | M8: =IF(OR(D8="",E8=""),"",ROUND(((E8-D8)*24)-((G8-F8)*24)-((H8+I8)/60),2)) -> 9.57 | N8: =IF(OR($D8="",$S8=""),"",IFERROR(MAX(0,ROUND(($D8-INDEX(Config!$C$15:$C$18,MATCH($S8,Config!$B$15:$B$18,0)))*24*60,0)),"")) -> 0 | O8: =IF(OR(F8="",G8=""),"",ROUND((G8-F8)*24*60,0)) -> 6 | P8: =IF(O8="","",O8+H8+I8) -> 36 | Q8: =IF(OR($P8="",$S8=""),"",IFERROR($P8-INDEX(Config!$E$15:$E$18,MATCH($S8,Config!$B$15:$B$18,0)),"")) -> -24 | R8: =IF($A8="","",IF($D8="","Ausente",IF($N8="","",IF($N8>0,"Atrasado","Puntual")))) -> Puntual | S8: =IF(OR($A8="",$C8=""),"",IFERROR(INDEX(Turno!$C$3:$V$32,MATCH($C8,Turno!$B$3:$B$32,0),MATCH(DAY($A8),Turno!$C$1:$V$1,0)),"")) -> A | T8: =IF(OR($E8="",$S8=""),"",IFERROR(MAX(0,ROUND((INDEX(Config!$D$15:$D$18,MATCH($S8,Config!$B$15:$B$18,0))-$E8)*1440,0)),"")) -> 0 | U8: =IF(OR($N8="",$T8=""),"",IFERROR(MAX(0,1-($N8+$T8+MAX(0,N($Q8)))/ROUND((INDEX(Config!$D$15:$D$18,MATCH($S8,Config!$B$15:$B$18,0))-INDEX(Config!$C$15:$C$18,MATCH($S8,Config!$B$15:$B$18,0)))*1440,0)),"")) -> 1
A9: 46237 | B9: 13026344-5 | C9: =IFERROR(INDEX(Ejecutivos!$B$2:$B$100,MATCH(B9,Ejecutivos!$A$2:$A$100,0)),"") -> KATIA HALD | D9: 08:30 | E9: 18:37 | F9: 15:32 | G9: 16:32 | H9: 18 | I9: 16 | J9: 10 | K9: 1 | L9: 0 | M9: =IF(OR(D9="",E9=""),"",ROUND(((E9-D9)*24)-((G9-F9)*24)-((H9+I9)/60),2)) -> 8.55 | N9: =IF(OR($D9="",$S9=""),"",IFERROR(MAX(0,ROUND(($D9-INDEX(Config!$C$15:$C$18,MATCH($S9,Config!$B$15:$B$18,0)))*24*60,0)),"")) -> 0 | O9: =IF(OR(F9="",G9=""),"",ROUND((G9-F9)*24*60,0)) -> 60 | P9: =IF(O9="","",O9+H9+I9) -> 94 | Q9: =IF(OR($P9="",$S9=""),"",IFERROR($P9-INDEX(Config!$E$15:$E$18,MATCH($S9,Config!$B$15:$B$18,0)),"")) -> 34 | R9: =IF($A9="","",IF($D9="","Ausente",IF($N9="","",IF($N9>0,"Atrasado","Puntual")))) -> Puntual | S9: =IF(OR($A9="",$C9=""),"",IFERROR(INDEX(Turno!$C$3:$V$32,MATCH($C9,Turno!$B$3:$B$32,0),MATCH(DAY($A9),Turno!$C$1:$V$1,0)),"")) -> A | T9: =IF(OR($E9="",$S9=""),"",IFERROR(MAX(0,ROUND((INDEX(Config!$D$15:$D$18,MATCH($S9,Config!$B$15:$B$18,0))-$E9)*1440,0)),"")) -> 0 | U9: =IF(OR($N9="",$T9=""),"",IFERROR(MAX(0,1-($N9+$T9+MAX(0,N($Q9)))/ROUND((INDEX(Config!$D$15:$D$18,MATCH($S9,Config!$B$15:$B$18,0))-INDEX(Config!$C$15:$C$18,MATCH($S9,Config!$B$15:$B$18,0)))*1440,0)),"")) -> 0.94333333
A10: 46237 | B10: 13638765-0 | C10: =IFERROR(INDEX(Ejecutivos!$B$2:$B$100,MATCH(B10,Ejecutivos!$A$2:$A$100,0)),"") -> MANUEL MONSALVE | D10: 08:28 | E10: 18:23 | F10: 15:05 | G10: 15:23 | H10: 0 | I10: 0 | J10: 0 | K10: 0 | L10: 0 | M10: =IF(OR(D10="",E10=""),"",ROUND(((E10-D10)*24)-((G10-F10)*24)-((H10+I10)/60),2)) -> 9.62 | N10: =IF(OR($D10="",$S10=""),"",IFERROR(MAX(0,ROUND(($D10-INDEX(Config!$C$15:$C$18,MATCH($S10,Config!$B$15:$B$18,0)))*24*60,0)),"")) -> 0 | O10: =IF(OR(F10="",G10=""),"",ROUND((G10-F10)*24*60,0)) -> 18 | P10: =IF(O10="","",O10+H10+I10) -> 18 | Q10: =IF(OR($P10="",$S10=""),"",IFERROR($P10-INDEX(Config!$E$15:$E$18,MATCH($S10,Config!$B$15:$B$18,0)),"")) -> -42 | R10: =IF($A10="","",IF($D10="","Ausente",IF($N10="","",IF($N10>0,"Atrasado","Puntual")))) -> Puntual | S10: =IF(OR($A10="",$C10=""),"",IFERROR(INDEX(Turno!$C$3:$V$32,MATCH($C10,Turno!$B$3:$B$32,0),MATCH(DAY($A10),Turno!$C$1:$V$1,0)),"")) -> A | T10: =IF(OR($E10="",$S10=""),"",IFERROR(MAX(0,ROUND((INDEX(Config!$D$15:$D$18,MATCH($S10,Config!$B$15:$B$18,0))-$E10)*1440,0)),"")) -> 7 | U10: =IF(OR($N10="",$T10=""),"",IFERROR(MAX(0,1-($N10+$T10+MAX(0,N($Q10)))/ROUND((INDEX(Config!$D$15:$D$18,MATCH($S10,Config!$B$15:$B$18,0))-INDEX(Config!$C$15:$C$18,MATCH($S10,Config!$B$15:$B$18,0)))*1440,0)),"")) -> 0.98833333
A11: 46237 | B11: 13337549-K | C11: =IFERROR(INDEX(Ejecutivos!$B$2:$B$100,MATCH(B11,Ejecutivos!$A$2:$A$100,0)),"") -> MANUELA ASTUDILLO | D11: 08:31 | E11: 18:01 | F11: 14:30 | G11: 15:00 | H11: 15 | I11: 16 | J11: 22 | K11: 3 | L11: 0 | M11: =IF(OR(D11="",E11=""),"",ROUND(((E11-D11)*24)-((G11-F11)*24)-((H11+I11)/60),2)) -> 8.48 | N11: =IF(OR($D11="",$S11=""),"",IFERROR(MAX(0,ROUND(($D11-INDEX(Config!$C$15:$C$18,MATCH($S11,Config!$B$15:$B$18,0)))*24*60,0)),"")) -> 1 | O11: =IF(OR(F11="",G11=""),"",ROUND((G11-F11)*24*60,0)) -> 30 | P11: =IF(O11="","",O11+H11+I11) -> 61 | Q11: =IF(OR($P11="",$S11=""),"",IFERROR($P11-INDEX(Config!$E$15:$E$18,MATCH($S11,Config!$B$15:$B$18,0)),"")) -> 1 | R11: =IF($A11="","",IF($D11="","Ausente",IF($N11="","",IF($N11>0,"Atrasado","Puntual")))) -> Atrasado | S11: =IF(OR($A11="",$C11=""),"",IFERROR(INDEX(Turno!$C$3:$V$32,MATCH($C11,Turno!$B$3:$B$32,0),MATCH(DAY($A11),Turno!$C$1:$V$1,0)),"")) -> A | T11: =IF(OR($E11="",$S11=""),"",IFERROR(MAX(0,ROUND((INDEX(Config!$D$15:$D$18,MATCH($S11,Config!$B$15:$B$18,0))-$E11)*1440,0)),"")) -> 29 | U11: =IF(OR($N11="",$T11=""),"",IFERROR(MAX(0,1-($N11+$T11+MAX(0,N($Q11)))/ROUND((INDEX(Config!$D$15:$D$18,MATCH($S11,Config!$B$15:$B$18,0))-INDEX(Config!$C$15:$C$18,MATCH($S11,Config!$B$15:$B$18,0)))*1440,0)),"")) -> 0.94833333
A12: 46237 | B12: 18123009-6 | C12: =IFERROR(INDEX(Ejecutivos!$B$2:$B$100,MATCH(B12,Ejecutivos!$A$2:$A$100,0)),"") -> MAXIMILIANO OLIVARES | D12: 08:31 | E12: 16:34 | F12: 0 | G12: 0 | H12: 15 | I12: 7 | J12: 12 | K12: 4 | L12: 0 | M12: =IF(OR(D12="",E12=""),"",ROUND(((E12-D12)*24)-((G12-F12)*24)-((H12+I12)/60),2)) -> 7.68 | N12: =IF(OR($D12="",$S12=""),"",IFERROR(MAX(0,ROUND(($D12-INDEX(Config!$C$15:$C$18,MATCH($S12,Config!$B$15:$B$18,0)))*24*60,0)),"")) -> 1 | O12: =IF(OR(F12="",G12=""),"",ROUND((G12-F12)*24*60,0)) -> 0 | P12: =IF(O12="","",O12+H12+I12) -> 22 | Q12: =IF(OR($P12="",$S12=""),"",IFERROR($P12-INDEX(Config!$E$15:$E$18,MATCH($S12,Config!$B$15:$B$18,0)),"")) -> -38 | R12: =IF($A12="","",IF($D12="","Ausente",IF($N12="","",IF($N12>0,"Atrasado","Puntual")))) -> Atrasado | S12: =IF(OR($A12="",$C12=""),"",IFERROR(INDEX(Turno!$C$3:$V$32,MATCH($C12,Turno!$B$3:$B$32,0),MATCH(DAY($A12),Turno!$C$1:$V$1,0)),"")) -> C | T12: =IF(OR($E12="",$S12=""),"",IFERROR(MAX(0,ROUND((INDEX(Config!$D$15:$D$18,MATCH($S12,Config!$B$15:$B$18,0))-$E12)*1440,0)),"")) -> 0 | U12: =IF(OR($N12="",$T12=""),"",IFERROR(MAX(0,1-($N12+$T12+MAX(0,N($Q12)))/ROUND((INDEX(Config!$D$15:$D$18,MATCH($S12,Config!$B$15:$B$18,0))-INDEX(Config!$C$15:$C$18,MATCH($S12,Config!$B$15:$B$18,0)))*1440,0)),"")) -> 0.99791667
A13: 46237 | B13: 19421111-2 | C13: =IFERROR(INDEX(Ejecutivos!$B$2:$B$100,MATCH(B13,Ejecutivos!$A$2:$A$100,0)),"") -> MELISSA SALGADO | D13: 08:32 | E13: 17:04 | F13: 12:38 | G13: 13:08 | H13: 15 | I13: 16 | J13: 30 | K13: 5 | L13: 0 | M13: =IF(OR(D13="",E13=""),"",ROUND(((E13-D13)*24)-((G13-F13)*24)-((H13+I13)/60),2)) -> 7.52 | N13: =IF(OR($D13="",$S13=""),"",IFERROR(MAX(0,ROUND(($D13-INDEX(Config!$C$15:$C$18,MATCH($S13,Config!$B$15:$B$18,0)))*24*60,0)),"")) -> 2 | O13: =IF(OR(F13="",G13=""),"",ROUND((G13-F13)*24*60,0)) -> 30 | P13: =IF(O13="","",O13+H13+I13) -> 61 | Q13: =IF(OR($P13="",$S13=""),"",IFERROR($P13-INDEX(Config!$E$15:$E$18,MATCH($S13,Config!$B$15:$B$18,0)),"")) -> 1 | R13: =IF($A13="","",IF($D13="","Ausente",IF($N13="","",IF($N13>0,"Atrasado","Puntual")))) -> Atrasado | S13: =IF(OR($A13="",$C13=""),"",IFERROR(INDEX(Turno!$C$3:$V$32,MATCH($C13,Turno!$B$3:$B$32,0),MATCH(DAY($A13),Turno!$C$1:$V$1,0)),"")) -> B | T13: =IF(OR($E13="",$S13=""),"",IFERROR(MAX(0,ROUND((INDEX(Config!$D$15:$D$18,MATCH($S13,Config!$B$15:$B$18,0))-$E13)*1440,0)),"")) -> 26 | U13: =IF(OR($N13="",$T13=""),"",IFERROR(MAX(0,1-($N13+$T13+MAX(0,N($Q13)))/ROUND((INDEX(Config!$D$15:$D$18,MATCH($S13,Config!$B$15:$B$18,0))-INDEX(Config!$C$15:$C$18,MATCH($S13,Config!$B$15:$B$18,0)))*1440,0)),"")) -> 0.9462963
A14: 46237 | B14: 27105214-6 | C14: =IFERROR(INDEX(Ejecutivos!$B$2:$B$100,MATCH(B14,Ejecutivos!$A$2:$A$100,0)),"") -> NANCI MENDEZ | D14: 08:26 | E14: 18:32 | F14: 12:58 | G14: 13:54 | H14: 15 | I14: 18 | J14: 0 | K14: 0 | L14: 0 | M14: =IF(OR(D14="",E14=""),"",ROUND(((E14-D14)*24)-((G14-F14)*24)-((H14+I14)/60),2)) -> 8.62 | N14: =IF(OR($D14="",$S14=""),"",IFERROR(MAX(0,ROUND(($D14-INDEX(Config!$C$15:$C$18,MATCH($S14,Config!$B$15:$B$18,0)))*24*60,0)),"")) -> 0 | O14: =IF(OR(F14="",G14=""),"",ROUND((G14-F14)*24*60,0)) -> 56 | P14: =IF(O14="","",O14+H14+I14) -> 89 | Q14: =IF(OR($P14="",$S14=""),"",IFERROR($P14-INDEX(Config!$E$15:$E$18,MATCH($S14,Config!$B$15:$B$18,0)),"")) -> 29 | R14: =IF($A14="","",IF($D14="","Ausente",IF($N14="","",IF($N14>0,"Atrasado","Puntual")))) -> Puntual | S14: =IF(OR($A14="",$C14=""),"",IFERROR(INDEX(Turno!$C$3:$V$32,MATCH($C14,Turno!$B$3:$B$32,0),MATCH(DAY($A14),Turno!$C$1:$V$1,0)),"")) -> B | T14: =IF(OR($E14="",$S14=""),"",IFERROR(MAX(0,ROUND((INDEX(Config!$D$15:$D$18,MATCH($S14,Config!$B$15:$B$18,0))-$E14)*1440,0)),"")) -> 0 | U14: =IF(OR($N14="",$T14=""),"",IFERROR(MAX(0,1-($N14+$T14+MAX(0,N($Q14)))/ROUND((INDEX(Config!$D$15:$D$18,MATCH($S14,Config!$B$15:$B$18,0))-INDEX(Config!$C$15:$C$18,MATCH($S14,Config!$B$15:$B$18,0)))*1440,0)),"")) -> 0.9462963
A15: 46237 | B15: 20828148-8 | C15: =IFERROR(INDEX(Ejecutivos!$B$2:$B$100,MATCH(B15,Ejecutivos!$A$2:$A$100,0)),"") -> TOMAS MAULEN | D15: 08:32 | E15: 18:34 | F15: 15:03 | G15: 16:05 | H15: 18 | I15: 3 | J15: 61 | K15: 7 | L15: 0 | M15: =IF(OR(D15="",E15=""),"",ROUND(((E15-D15)*24)-((G15-F15)*24)-((H15+I15)/60),2)) -> 8.65 | N15: =IF(OR($D15="",$S15=""),"",IFERROR(MAX(0,ROUND(($D15-INDEX(Config!$C$15:$C$18,MATCH($S15,Config!$B$15:$B$18,0)))*24*60,0)),"")) -> 2 | O15: =IF(OR(F15="",G15=""),"",ROUND((G15-F15)*24*60,0)) -> 62 | P15: =IF(O15="","",O15+H15+I15) -> 83 | Q15: =IF(OR($P15="",$S15=""),"",IFERROR($P15-INDEX(Config!$E$15:$E$18,MATCH($S15,Config!$B$15:$B$18,0)),"")) -> 23 | R15: =IF($A15="","",IF($D15="","Ausente",IF($N15="","",IF($N15>0,"Atrasado","Puntual")))) -> Atrasado | S15: =IF(OR($A15="",$C15=""),"",IFERROR(INDEX(Turno!$C$3:$V$32,MATCH($C15,Turno!$B$3:$B$32,0),MATCH(DAY($A15),Turno!$C$1:$V$1,0)),"")) -> A | T15: =IF(OR($E15="",$S15=""),"",IFERROR(MAX(0,ROUND((INDEX(Config!$D$15:$D$18,MATCH($S15,Config!$B$15:$B$18,0))-$E15)*1440,0)),"")) -> 0 | U15: =IF(OR($N15="",$T15=""),"",IFERROR(MAX(0,1-($N15+$T15+MAX(0,N($Q15)))/ROUND((INDEX(Config!$D$15:$D$18,MATCH($S15,Config!$B$15:$B$18,0))-INDEX(Config!$C$15:$C$18,MATCH($S15,Config!$B$15:$B$18,0)))*1440,0)),"")) -> 0.95833333
A16: 46238 | B16: 26612947-5 | C16: =IFERROR(INDEX(Ejecutivos!$B$2:$B$100,MATCH(B16,Ejecutivos!$A$2:$A$100,0)),"") -> ALEJANDRA CHACON | D16: 08:30 | E16: 18:31 | F16: 14:04 | G16: 15:05 | H16: 16 | I16: 16 | J16: 26 | K16: 3 | L16: 0 | M16: =IF(OR(D16="",E16=""),"",ROUND(((E16-D16)*24)-((G16-F16)*24)-((H16+I16)/60),2)) -> 8.47 | N16: =IF(OR($D16="",$S16=""),"",IFERROR(MAX(0,ROUND(($D16-INDEX(Config!$C$15:$C$18,MATCH($S16,Config!$B$15:$B$18,0)))*24*60,0)),"")) -> 0 | O16: =IF(OR(F16="",G16=""),"",ROUND((G16-F16)*24*60,0)) -> 61 | P16: =IF(O16="","",O16+H16+I16) -> 93 | Q16: =IF(OR($P16="",$S16=""),"",IFERROR($P16-INDEX(Config!$E$15:$E$18,MATCH($S16,Config!$B$15:$B$18,0)),"")) -> 33 | R16: =IF($A16="","",IF($D16="","Ausente",IF($N16="","",IF($N16>0,"Atrasado","Puntual")))) -> Puntual | S16: =IF(OR($A16="",$C16=""),"",IFERROR(INDEX(Turno!$C$3:$V$32,MATCH($C16,Turno!$B$3:$B$32,0),MATCH(DAY($A16),Turno!$C$1:$V$1,0)),"")) -> A | T16: =IF(OR($E16="",$S16=""),"",IFERROR(MAX(0,ROUND((INDEX(Config!$D$15:$D$18,MATCH($S16,Config!$B$15:$B$18,0))-$E16)*1440,0)),"")) -> 0 | U16: =IF(OR($N16="",$T16=""),"",IFERROR(MAX(0,1-($N16+$T16+MAX(0,N($Q16)))/ROUND((INDEX(Config!$D$15:$D$18,MATCH($S16,Config!$B$15:$B$18,0))-INDEX(Config!$C$15:$C$18,MATCH($S16,Config!$B$15:$B$18,0)))*1440,0)),"")) -> 0.945
A17: 46238 | B17: 13093458-7 | C17: =IFERROR(INDEX(Ejecutivos!$B$2:$B$100,MATCH(B17,Ejecutivos!$A$2:$A$100,0)),"") -> ALEJANDRA ORELLANA | D17: 09:30 | E17: 18:01 | F17: 12:04 | G17: 12:34 | H17: 15 | I17: 15 | J17: 0 | K17: 0 | L17: 0 | M17: =IF(OR(D17="",E17=""),"",ROUND(((E17-D17)*24)-((G17-F17)*24)-((H17+I17)/60),2)) -> 7.52 | N17: =IF(OR($D17="",$S17=""),"",IFERROR(MAX(0,ROUND(($D17-INDEX(Config!$C$15:$C$18,MATCH($S17,Config!$B$15:$B$18,0)))*24*60,0)),"")) -> 0 | O17: =IF(OR(F17="",G17=""),"",ROUND((G17-F17)*24*60,0)) -> 30 | P17: =IF(O17="","",O17+H17+I17) -> 60 | Q17: =IF(OR($P17="",$S17=""),"",IFERROR($P17-INDEX(Config!$E$15:$E$18,MATCH($S17,Config!$B$15:$B$18,0)),"")) -> 0 | R17: =IF($A17="","",IF($D17="","Ausente",IF($N17="","",IF($N17>0,"Atrasado","Puntual")))) -> Puntual | S17: =IF(OR($A17="",$C17=""),"",IFERROR(INDEX(Turno!$C$3:$V$32,MATCH($C17,Turno!$B$3:$B$32,0),MATCH(DAY($A17),Turno!$C$1:$V$1,0)),"")) -> D | T17: =IF(OR($E17="",$S17=""),"",IFERROR(MAX(0,ROUND((INDEX(Config!$D$15:$D$18,MATCH($S17,Config!$B$15:$B$18,0))-$E17)*1440,0)),"")) -> 29 | U17: =IF(OR($N17="",$T17=""),"",IFERROR(MAX(0,1-($N17+$T17+MAX(0,N($Q17)))/ROUND((INDEX(Config!$D$15:$D$18,MATCH($S17,Config!$B$15:$B$18,0))-INDEX(Config!$C$15:$C$18,MATCH($S17,Config!$B$15:$B$18,0)))*1440,0)),"")) -> 0.9462963
A18: 46238 | B18: 13336644-k | C18: =IFERROR(INDEX(Ejecutivos!$B$2:$B$100,MATCH(B18,Ejecutivos!$A$2:$A$100,0)),"") -> ANA ASTORGA | D18: 08:32 | E18: 15:46 | F18: 13:35 | G18: 14:01 | H18: 15 | I18: 35 | J18: 28 | K18: 4 | L18: 0 | M18: =IF(OR(D18="",E18=""),"",ROUND(((E18-D18)*24)-((G18-F18)*24)-((H18+I18)/60),2)) -> 5.97 | N18: =IF(OR($D18="",$S18=""),"",IFERROR(MAX(0,ROUND(($D18-INDEX(Config!$C$15:$C$18,MATCH($S18,Config!$B$15:$B$18,0)))*24*60,0)),"")) -> 2 | O18: =IF(OR(F18="",G18=""),"",ROUND((G18-F18)*24*60,0)) -> 26 | P18: =IF(O18="","",O18+H18+I18) -> 76 | Q18: =IF(OR($P18="",$S18=""),"",IFERROR($P18-INDEX(Config!$E$15:$E$18,MATCH($S18,Config!$B$15:$B$18,0)),"")) -> 16 | R18: =IF($A18="","",IF($D18="","Ausente",IF($N18="","",IF($N18>0,"Atrasado","Puntual")))) -> Atrasado | S18: =IF(OR($A18="",$C18=""),"",IFERROR(INDEX(Turno!$C$3:$V$32,MATCH($C18,Turno!$B$3:$B$32,0),MATCH(DAY($A18),Turno!$C$1:$V$1,0)),"")) -> C | T18: =IF(OR($E18="",$S18=""),"",IFERROR(MAX(0,ROUND((INDEX(Config!$D$15:$D$18,MATCH($S18,Config!$B$15:$B$18,0))-$E18)*1440,0)),"")) -> 44 | U18: =IF(OR($N18="",$T18=""),"",IFERROR(MAX(0,1-($N18+$T18+MAX(0,N($Q18)))/ROUND((INDEX(Config!$D$15:$D$18,MATCH($S18,Config!$B$15:$B$18,0))-INDEX(Config!$C$15:$C$18,MATCH($S18,Config!$B$15:$B$18,0)))*1440,0)),"")) -> 0.87083333
A19: 46238 | B19: 18637622-6 | C19: =IFERROR(INDEX(Ejecutivos!$B$2:$B$100,MATCH(B19,Ejecutivos!$A$2:$A$100,0)),"") -> DANIELA RODRIGUEZ | D19: 11:00 | E19: 18:31 | F19: 15:06 | G19: 16:08 | H19: 15 | I19: 0 | J19: 28 | K19: 7 | L19: 0 | M19: =IF(OR(D19="",E19=""),"",ROUND(((E19-D19)*24)-((G19-F19)*24)-((H19+I19)/60),2)) -> 6.23 | N19: =IF(OR($D19="",$S19=""),"",IFERROR(MAX(0,ROUND(($D19-INDEX(Config!$C$15:$C$18,MATCH($S19,Config!$B$15:$B$18,0)))*24*60,0)),"")) -> 150 | O19: =IF(OR(F19="",G19=""),"",ROUND((G19-F19)*24*60,0)) -> 62 | P19: =IF(O19="","",O19+H19+I19) -> 77 | Q19: =IF(OR($P19="",$S19=""),"",IFERROR($P19-INDEX(Config!$E$15:$E$18,MATCH($S19,Config!$B$15:$B$18,0)),"")) -> 17 | R19: =IF($A19="","",IF($D19="","Ausente",IF($N19="","",IF($N19>0,"Atrasado","Puntual")))) -> Atrasado | S19: =IF(OR($A19="",$C19=""),"",IFERROR(INDEX(Turno!$C$3:$V$32,MATCH($C19,Turno!$B$3:$B$32,0),MATCH(DAY($A19),Turno!$C$1:$V$1,0)),"")) -> A | T19: =IF(OR($E19="",$S19=""),"",IFERROR(MAX(0,ROUND((INDEX(Config!$D$15:$D$18,MATCH($S19,Config!$B$15:$B$18,0))-$E19)*1440,0)),"")) -> 0 | U19: =IF(OR($N19="",$T19=""),"",IFERROR(MAX(0,1-($N19+$T19+MAX(0,N($Q19)))/ROUND((INDEX(Config!$D$15:$D$18,MATCH($S19,Config!$B$15:$B$18,0))-INDEX(Config!$C$15:$C$18,MATCH($S19,Config!$B$15:$B$18,0)))*1440,0)),"")) -> 0.72166667
A20: 46238 | B20: 14364155-4 | C20: =IFERROR(INDEX(Ejecutivos!$B$2:$B$100,MATCH(B20,Ejecutivos!$A$2:$A$100,0)),"") -> ELSA GONGORA | D20: 08:30 | E20: 20:15 | F20: 13:02 | G20: 14:02 | H20: 15 | I20: 15 | J20: 7 | K20: 2 | L20: 0 | M20: =IF(OR(D20="",E20=""),"",ROUND(((E20-D20)*24)-((G20-F20)*24)-((H20+I20)/60),2)) -> 10.25 | N20: =IF(OR($D20="",$S20=""),"",IFERROR(MAX(0,ROUND(($D20-INDEX(Config!$C$15:$C$18,MATCH($S20,Config!$B$15:$B$18,0)))*24*60,0)),"")) -> 0 | O20: =IF(OR(F20="",G20=""),"",ROUND((G20-F20)*24*60,0)) -> 60 | P20: =IF(O20="","",O20+H20+I20) -> 90 | Q20: =IF(OR($P20="",$S20=""),"",IFERROR($P20-INDEX(Config!$E$15:$E$18,MATCH($S20,Config!$B$15:$B$18,0)),"")) -> 30 | R20: =IF($A20="","",IF($D20="","Ausente",IF($N20="","",IF($N20>0,"Atrasado","Puntual")))) -> Puntual | S20: =IF(OR($A20="",$C20=""),"",IFERROR(INDEX(Turno!$C$3:$V$32,MATCH($C20,Turno!$B$3:$B$32,0),MATCH(DAY($A20),Turno!$C$1:$V$1,0)),"")) -> A | T20: =IF(OR($E20="",$S20=""),"",IFERROR(MAX(0,ROUND((INDEX(Config!$D$15:$D$18,MATCH($S20,Config!$B$15:$B$18,0))-$E20)*1440,0)),"")) -> 0 | U20: =IF(OR($N20="",$T20=""),"",IFERROR(MAX(0,1-($N20+$T20+MAX(0,N($Q20)))/ROUND((INDEX(Config!$D$15:$D$18,MATCH($S20,Config!$B$15:$B$18,0))-INDEX(Config!$C$15:$C$18,MATCH($S20,Config!$B$15:$B$18,0)))*1440,0)),"")) -> 0.95
A21: 46238 | B21: 16117577-3 | C21: =IFERROR(INDEX(Ejecutivos!$B$2:$B$100,MATCH(B21,Ejecutivos!$A$2:$A$100,0)),"") -> JOHANA LLANCAPICHUN | D21: 08:30 | E21: 20:16 | F21: 14:11 | G21: 15:10 | H21: 15 | I21: 0 | J21: 7 | K21: 1 | L21: 0 | M21: =IF(OR(D21="",E21=""),"",ROUND(((E21-D21)*24)-((G21-F21)*24)-((H21+I21)/60),2)) -> 10.53 | N21: =IF(OR($D21="",$S21=""),"",IFERROR(MAX(0,ROUND(($D21-INDEX(Config!$C$15:$C$18,MATCH($S21,Config!$B$15:$B$18,0)))*24*60,0)),"")) -> 0 | O21: =IF(OR(F21="",G21=""),"",ROUND((G21-F21)*24*60,0)) -> 59 | P21: =IF(O21="","",O21+H21+I21) -> 74 | Q21: =IF(OR($P21="",$S21=""),"",IFERROR($P21-INDEX(Config!$E$15:$E$18,MATCH($S21,Config!$B$15:$B$18,0)),"")) -> 14 | R21: =IF($A21="","",IF($D21="","Ausente",IF($N21="","",IF($N21>0,"Atrasado","Puntual")))) -> Puntual | S21: =IF(OR($A21="",$C21=""),"",IFERROR(INDEX(Turno!$C$3:$V$32,MATCH($C21,Turno!$B$3:$B$32,0),MATCH(DAY($A21),Turno!$C$1:$V$1,0)),"")) -> A | T21: =IF(OR($E21="",$S21=""),"",IFERROR(MAX(0,ROUND((INDEX(Config!$D$15:$D$18,MATCH($S21,Config!$B$15:$B$18,0))-$E21)*1440,0)),"")) -> 0 | U21: =IF(OR($N21="",$T21=""),"",IFERROR(MAX(0,1-($N21+$T21+MAX(0,N($Q21)))/ROUND((INDEX(Config!$D$15:$D$18,MATCH($S21,Config!$B$15:$B$18,0))-INDEX(Config!$C$15:$C$18,MATCH($S21,Config!$B$15:$B$18,0)))*1440,0)),"")) -> 0.97666667
A22: 46238 | B22: 13026344-5 | C22: =IFERROR(INDEX(Ejecutivos!$B$2:$B$100,MATCH(B22,Ejecutivos!$A$2:$A$100,0)),"") -> KATIA HALD | D22: 08:30 | E22: 20:24 | F22: 15:11 | G22: 16:12 | H22: 16 | I22: 16 | J22: 0 | K22: 0 | L22: 0 | M22: =IF(OR(D22="",E22=""),"",ROUND(((E22-D22)*24)-((G22-F22)*24)-((H22+I22)/60),2)) -> 10.35 | N22: =IF(OR($D22="",$S22=""),"",IFERROR(MAX(0,ROUND(($D22-INDEX(Config!$C$15:$C$18,MATCH($S22,Config!$B$15:$B$18,0)))*24*60,0)),"")) -> 0 | O22: =IF(OR(F22="",G22=""),"",ROUND((G22-F22)*24*60,0)) -> 61 | P22: =IF(O22="","",O22+H22+I22) -> 93 | Q22: =IF(OR($P22="",$S22=""),"",IFERROR($P22-INDEX(Config!$E$15:$E$18,MATCH($S22,Config!$B$15:$B$18,0)),"")) -> 33 | R22: =IF($A22="","",IF($D22="","Ausente",IF($N22="","",IF($N22>0,"Atrasado","Puntual")))) -> Puntual | S22: =IF(OR($A22="",$C22=""),"",IFERROR(INDEX(Turno!$C$3:$V$32,MATCH($C22,Turno!$B$3:$B$32,0),MATCH(DAY($A22),Turno!$C$1:$V$1,0)),"")) -> A | T22: =IF(OR($E22="",$S22=""),"",IFERROR(MAX(0,ROUND((INDEX(Config!$D$15:$D$18,MATCH($S22,Config!$B$15:$B$18,0))-$E22)*1440,0)),"")) -> 0 | U22: =IF(OR($N22="",$T22=""),"",IFERROR(MAX(0,1-($N22+$T22+MAX(0,N($Q22)))/ROUND((INDEX(Config!$D$15:$D$18,MATCH($S22,Config!$B$15:$B$18,0))-INDEX(Config!$C$15:$C$18,MATCH($S22,Config!$B$15:$B$18,0)))*1440,0)),"")) -> 0.945
A23: 46238 | B23: 13638765-0 | C23: =IFERROR(INDEX(Ejecutivos!$B$2:$B$100,MATCH(B23,Ejecutivos!$A$2:$A$100,0)),"") -> MANUEL MONSALVE | D23: 08:28 | E23: 20:31 | F23: 13:27 | G23: 13:54 | H23: 0 | I23: 0 | J23: 0 | K23: 0 | L23: 0 | M23: =IF(OR(D23="",E23=""),"",ROUND(((E23-D23)*24)-((G23-F23)*24)-((H23+I23)/60),2)) -> 11.6 | N23: =IF(OR($D23="",$S23=""),"",IFERROR(MAX(0,ROUND(($D23-INDEX(Config!$C$15:$C$18,MATCH($S23,Config!$B$15:$B$18,0)))*24*60,0)),"")) -> 0 | O23: =IF(OR(F23="",G23=""),"",ROUND((G23-F23)*24*60,0)) -> 27 | P23: =IF(O23="","",O23+H23+I23) -> 27 | Q23: =IF(OR($P23="",$S23=""),"",IFERROR($P23-INDEX(Config!$E$15:$E$18,MATCH($S23,Config!$B$15:$B$18,0)),"")) -> -33 | R23: =IF($A23="","",IF($D23="","Ausente",IF($N23="","",IF($N23>0,"Atrasado","Puntual")))) -> Puntual | S23: =IF(OR($A23="",$C23=""),"",IFERROR(INDEX(Turno!$C$3:$V$32,MATCH($C23,Turno!$B$3:$B$32,0),MATCH(DAY($A23),Turno!$C$1:$V$1,0)),"")) -> A | T23: =IF(OR($E23="",$S23=""),"",IFERROR(MAX(0,ROUND((INDEX(Config!$D$15:$D$18,MATCH($S23,Config!$B$15:$B$18,0))-$E23)*1440,0)),"")) -> 0 | U23: =IF(OR($N23="",$T23=""),"",IFERROR(MAX(0,1-($N23+$T23+MAX(0,N($Q23)))/ROUND((INDEX(Config!$D$15:$D$18,MATCH($S23,Config!$B$15:$B$18,0))-INDEX(Config!$C$15:$C$18,MATCH($S23,Config!$B$15:$B$18,0)))*1440,0)),"")) -> 1
A24: 46238 | B24: 13337549-K | C24: =IFERROR(INDEX(Ejecutivos!$B$2:$B$100,MATCH(B24,Ejecutivos!$A$2:$A$100,0)),"") -> MANUELA ASTUDILLO | D24: 08:30 | E24: 18:31 | F24: 14:32 | G24: 15:32 | H24: 15 | I24: 15 | J24: 19 | K24: 3 | L24: 0 | M24: =IF(OR(D24="",E24=""),"",ROUND(((E24-D24)*24)-((G24-F24)*24)-((H24+I24)/60),2)) -> 8.52 | N24: =IF(OR($D24="",$S24=""),"",IFERROR(MAX(0,ROUND(($D24-INDEX(Config!$C$15:$C$18,MATCH($S24,Config!$B$15:$B$18,0)))*24*60,0)),"")) -> 0 | O24: =IF(OR(F24="",G24=""),"",ROUND((G24-F24)*24*60,0)) -> 60 | P24: =IF(O24="","",O24+H24+I24) -> 90 | Q24: =IF(OR($P24="",$S24=""),"",IFERROR($P24-INDEX(Config!$E$15:$E$18,MATCH($S24,Config!$B$15:$B$18,0)),"")) -> 30 | R24: =IF($A24="","",IF($D24="","Ausente",IF($N24="","",IF($N24>0,"Atrasado","Puntual")))) -> Puntual | S24: =IF(OR($A24="",$C24=""),"",IFERROR(INDEX(Turno!$C$3:$V$32,MATCH($C24,Turno!$B$3:$B$32,0),MATCH(DAY($A24),Turno!$C$1:$V$1,0)),"")) -> A | T24: =IF(OR($E24="",$S24=""),"",IFERROR(MAX(0,ROUND((INDEX(Config!$D$15:$D$18,MATCH($S24,Config!$B$15:$B$18,0))-$E24)*1440,0)),"")) -> 0 | U24: =IF(OR($N24="",$T24=""),"",IFERROR(MAX(0,1-($N24+$T24+MAX(0,N($Q24)))/ROUND((INDEX(Config!$D$15:$D$18,MATCH($S24,Config!$B$15:$B$18,0))-INDEX(Config!$C$15:$C$18,MATCH($S24,Config!$B$15:$B$18,0)))*1440,0)),"")) -> 0.95
... A27: 46238 | B27: 27105214-6 | C27: =IFERROR(INDEX(Ejecutivos!$B$2:$B$100,MATCH(B27,Ejecutivos!$A$2:$A$100,0)),"") -> NANCI MENDEZ | D27: 08:28 | E27: 17:30 | F27: 12:31 | G27: 13:31 | H27: 17 | I27: 18 | J27: 6 | K27: 1 | L27: 0 | M27: =IF(OR(D27="",E27=""),"",ROUND(((E27-D27)*24)-((G27-F27)*24)-((H27+I27)/60),2)) -> 7.45 | N27: =IF(OR($D27="",$S27=""),"",IFERROR(MAX(0,ROUND(($D27-INDEX(Config!$C$15:$C$18,MATCH($S27,Config!$B$15:$B$18,0)))*24*60,0)),"")) -> 0 | O27: =IF(OR(F27="",G27=""),"",ROUND((G27-F27)*24*60,0)) -> 60 | P27: =IF(O27="","",O27+H27+I27) -> 95 | Q27: =IF(OR($P27="",$S27=""),"",IFERROR($P27-INDEX(Config!$E$15:$E$18,MATCH($S27,Config!$B$15:$B$18,0)),"")) -> 35 | R27: =IF($A27="","",IF($D27="","Ausente",IF($N27="","",IF($N27>0,"Atrasado","Puntual")))) -> Puntual | S27: =IF(OR($A27="",$C27=""),"",IFERROR(INDEX(Turno!$C$3:$V$32,MATCH($C27,Turno!$B$3:$B$32,0),MATCH(DAY($A27),Turno!$C$1:$V$1,0)),"")) -> A | T27: =IF(OR($E27="",$S27=""),"",IFERROR(MAX(0,ROUND((INDEX(Config!$D$15:$D$18,MATCH($S27,Config!$B$15:$B$18,0))-$E27)*1440,0)),"")) -> 60 | U27: =IF(OR($N27="",$T27=""),"",IFERROR(MAX(0,1-($N27+$T27+MAX(0,N($Q27)))/ROUND((INDEX(Config!$D$15:$D$18,MATCH($S27,Config!$B$15:$B$18,0))-INDEX(Config!$C$15:$C$18,MATCH($S27,Config!$B$15:$B$18,0)))*1440,0)),"")) -> 0.84166667
A28: 46238 | B28: 20828148-8 | C28: =IFERROR(INDEX(Ejecutivos!$B$2:$B$100,MATCH(B28,Ejecutivos!$A$2:$A$100,0)),"") -> TOMAS MAULEN | D28: 08:37 | E28: 0.77083333 | F28: 0 | G28: 0 | H28: 17 | I28: 2 | J28: 65 | K28: 9 | L28: 0 | M28: =IF(OR(D28="",E28=""),"",ROUND(((E28-D28)*24)-((G28-F28)*24)-((H28+I28)/60),2)) -> 9.57 | N28: =IF(OR($D28="",$S28=""),"",IFERROR(MAX(0,ROUND(($D28-INDEX(Config!$C$15:$C$18,MATCH($S28,Config!$B$15:$B$18,0)))*24*60,0)),"")) -> 7 | O28: =IF(OR(F28="",G28=""),"",ROUND((G28-F28)*24*60,0)) -> 0 | P28: =IF(O28="","",O28+H28+I28) -> 19 | Q28: =IF(OR($P28="",$S28=""),"",IFERROR($P28-INDEX(Config!$E$15:$E$18,MATCH($S28,Config!$B$15:$B$18,0)),"")) -> -41 | R28: =IF($A28="","",IF($D28="","Ausente",IF($N28="","",IF($N28>0,"Atrasado","Puntual")))) -> Atrasado | S28: =IF(OR($A28="",$C28=""),"",IFERROR(INDEX(Turno!$C$3:$V$32,MATCH($C28,Turno!$B$3:$B$32,0),MATCH(DAY($A28),Turno!$C$1:$V$1,0)),"")) -> B | T28: =IF(OR($E28="",$S28=""),"",IFERROR(MAX(0,ROUND((INDEX(Config!$D$15:$D$18,MATCH($S28,Config!$B$15:$B$18,0))-$E28)*1440,0)),"")) -> 0 | U28: =IF(OR($N28="",$T28=""),"",IFERROR(MAX(0,1-($N28+$T28+MAX(0,N($Q28)))/ROUND((INDEX(Config!$D$15:$D$18,MATCH($S28,Config!$B$15:$B$18,0))-INDEX(Config!$C$15:$C$18,MATCH($S28,Config!$B$15:$B$18,0)))*1440,0)),"")) -> 0.98703704
A29: 46239 | B29: 26612947-5 | C29: =IFERROR(INDEX(Ejecutivos!$B$2:$B$100,MATCH(B29,Ejecutivos!$A$2:$A$100,0)),"") -> ALEJANDRA CHACON | D29: 08:29 | E29: 18:30 | F29: 14:30 | G29: 15:31 | H29: 16 | I29: 16 | J29: 31 | K29: 3 | L29: 0 | M29: =IF(OR(D29="",E29=""),"",ROUND(((E29-D29)*24)-((G29-F29)*24)-((H29+I29)/60),2)) -> 8.47 | N29: =IF(OR($D29="",$S29=""),"",IFERROR(MAX(0,ROUND(($D29-INDEX(Config!$C$15:$C$18,MATCH($S29,Config!$B$15:$B$18,0)))*24*60,0)),"")) -> 0 | O29: =IF(OR(F29="",G29=""),"",ROUND((G29-F29)*24*60,0)) -> 61 | P29: =IF(O29="","",O29+H29+I29) -> 93 | Q29: =IF(OR($P29="",$S29=""),"",IFERROR($P29-INDEX(Config!$E$15:$E$18,MATCH($S29,Config!$B$15:$B$18,0)),"")) -> 33 | R29: =IF($A29="","",IF($D29="","Ausente",IF($N29="","",IF($N29>0,"Atrasado","Puntual")))) -> Puntual | S29: =IF(OR($A29="",$C29=""),"",IFERROR(INDEX(Turno!$C$3:$V$32,MATCH($C29,Turno!$B$3:$B$32,0),MATCH(DAY($A29),Turno!$C$1:$V$1,0)),"")) -> A | T29: =IF(OR($E29="",$S29=""),"",IFERROR(MAX(0,ROUND((INDEX(Config!$D$15:$D$18,MATCH($S29,Config!$B$15:$B$18,0))-$E29)*1440,0)),"")) -> 0 | U29: =IF(OR($N29="",$T29=""),"",IFERROR(MAX(0,1-($N29+$T29+MAX(0,N($Q29)))/ROUND((INDEX(Config!$D$15:$D$18,MATCH($S29,Config!$B$15:$B$18,0))-INDEX(Config!$C$15:$C$18,MATCH($S29,Config!$B$15:$B$18,0)))*1440,0)),"")) -> 0.945
A30: 46239 | B30: 13093458-7 | C30: =IFERROR(INDEX(Ejecutivos!$B$2:$B$100,MATCH(B30,Ejecutivos!$A$2:$A$100,0)),"") -> ALEJANDRA ORELLANA | D30: 08:30 | E30: 18:00 | F30: 12:00 | G30: 12:30 | H30: 15 | I30: 15 | J30: 5 | K30: 1 | L30: 0 | M30: =IF(OR(D30="",E30=""),"",ROUND(((E30-D30)*24)-((G30-F30)*24)-((H30+I30)/60),2)) -> 8.5 | N30: =IF(OR($D30="",$S30=""),"",IFERROR(MAX(0,ROUND(($D30-INDEX(Config!$C$15:$C$18,MATCH($S30,Config!$B$15:$B$18,0)))*24*60,0)),"")) -> 0 | O30: =IF(OR(F30="",G30=""),"",ROUND((G30-F30)*24*60,0)) -> 30 | P30: =IF(O30="","",O30+H30+I30) -> 60 | Q30: =IF(OR($P30="",$S30=""),"",IFERROR($P30-INDEX(Config!$E$15:$E$18,MATCH($S30,Config!$B$15:$B$18,0)),"")) -> 0 | R30: =IF($A30="","",IF($D30="","Ausente",IF($N30="","",IF($N30>0,"Atrasado","Puntual")))) -> Puntual | S30: =IF(OR($A30="",$C30=""),"",IFERROR(INDEX(Turno!$C$3:$V$32,MATCH($C30,Turno!$B$3:$B$32,0),MATCH(DAY($A30),Turno!$C$1:$V$1,0)),"")) -> A | T30: =IF(OR($E30="",$S30=""),"",IFERROR(MAX(0,ROUND((INDEX(Config!$D$15:$D$18,MATCH($S30,Config!$B$15:$B$18,0))-$E30)*1440,0)),"")) -> 30 | U30: =IF(OR($N30="",$T30=""),"",IFERROR(MAX(0,1-($N30+$T30+MAX(0,N($Q30)))/ROUND((INDEX(Config!$D$15:$D$18,MATCH($S30,Config!$B$15:$B$18,0))-INDEX(Config!$C$15:$C$18,MATCH($S30,Config!$B$15:$B$18,0)))*1440,0)),"")) -> 0.95
A31: 46239 | B31: 18637622-6 | C31: =IFERROR(INDEX(Ejecutivos!$B$2:$B$100,MATCH(B31,Ejecutivos!$A$2:$A$100,0)),"") -> DANIELA RODRIGUEZ | D31: 08:30 | E31: 18:33 | F31: 15:35 | G31: 16:38 | H31: 17 | I31: 16 | J31: 16 | K31: 4 | L31: 0 | M31: =IF(OR(D31="",E31=""),"",ROUND(((E31-D31)*24)-((G31-F31)*24)-((H31+I31)/60),2)) -> 8.45 | N31: =IF(OR($D31="",$S31=""),"",IFERROR(MAX(0,ROUND(($D31-INDEX(Config!$C$15:$C$18,MATCH($S31,Config!$B$15:$B$18,0)))*24*60,0)),"")) -> 0 | O31: =IF(OR(F31="",G31=""),"",ROUND((G31-F31)*24*60,0)) -> 63 | P31: =IF(O31="","",O31+H31+I31) -> 96 | Q31: =IF(OR($P31="",$S31=""),"",IFERROR($P31-INDEX(Config!$E$15:$E$18,MATCH($S31,Config!$B$15:$B$18,0)),"")) -> 36 | R31: =IF($A31="","",IF($D31="","Ausente",IF($N31="","",IF($N31>0,"Atrasado","Puntual")))) -> Puntual | S31: =IF(OR($A31="",$C31=""),"",IFERROR(INDEX(Turno!$C$3:$V$32,MATCH($C31,Turno!$B$3:$B$32,0),MATCH(DAY($A31),Turno!$C$1:$V$1,0)),"")) -> A | T31: =IF(OR($E31="",$S31=""),"",IFERROR(MAX(0,ROUND((INDEX(Config!$D$15:$D$18,MATCH($S31,Config!$B$15:$B$18,0))-$E31)*1440,0)),"")) -> 0 | U31: =IF(OR($N31="",$T31=""),"",IFERROR(MAX(0,1-($N31+$T31+MAX(0,N($Q31)))/ROUND((INDEX(Config!$D$15:$D$18,MATCH($S31,Config!$B$15:$B$18,0))-INDEX(Config!$C$15:$C$18,MATCH($S31,Config!$B$15:$B$18,0)))*1440,0)),"")) -> 0.94
A32: 46239 | B32: 14364155-4 | C32: =IFERROR(INDEX(Ejecutivos!$B$2:$B$100,MATCH(B32,Ejecutivos!$A$2:$A$100,0)),"") -> ELSA GONGORA | D32: 09:31 | E32: 21:14 | F32: 13:09 | G32: 14:10 | H32: 15 | I32: 0 | J32: 9 | K32: 1 | L32: 0 | M32: =IF(OR(D32="",E32=""),"",ROUND(((E32-D32)*24)-((G32-F32)*24)-((H32+I32)/60),2)) -> 10.45 | N32: =IF(OR($D32="",$S32=""),"",IFERROR(MAX(0,ROUND(($D32-INDEX(Config!$C$15:$C$18,MATCH($S32,Config!$B$15:$B$18,0)))*24*60,0)),"")) -> 1 | O32: =IF(OR(F32="",G32=""),"",ROUND((G32-F32)*24*60,0)) -> 61 | P32: =IF(O32="","",O32+H32+I32) -> 76 | Q32: =IF(OR($P32="",$S32=""),"",IFERROR($P32-INDEX(Config!$E$15:$E$18,MATCH($S32,Config!$B$15:$B$18,0)),"")) -> 16 | R32: =IF($A32="","",IF($D32="","Ausente",IF($N32="","",IF($N32>0,"Atrasado","Puntual")))) -> Atrasado | S32: =IF(OR($A32="",$C32=""),"",IFERROR(INDEX(Turno!$C$3:$V$32,MATCH($C32,Turno!$B$3:$B$32,0),MATCH(DAY($A32),Turno!$C$1:$V$1,0)),"")) -> D | T32: =IF(OR($E32="",$S32=""),"",IFERROR(MAX(0,ROUND((INDEX(Config!$D$15:$D$18,MATCH($S32,Config!$B$15:$B$18,0))-$E32)*1440,0)),"")) -> 0 | U32: =IF(OR($N32="",$T32=""),"",IFERROR(MAX(0,1-($N32+$T32+MAX(0,N($Q32)))/ROUND((INDEX(Config!$D$15:$D$18,MATCH($S32,Config!$B$15:$B$18,0))-INDEX(Config!$C$15:$C$18,MATCH($S32,Config!$B$15:$B$18,0)))*1440,0)),"")) -> 0.96851852
A33: 46239 | B33: 16117577-3 | C33: =IFERROR(INDEX(Ejecutivos!$B$2:$B$100,MATCH(B33,Ejecutivos!$A$2:$A$100,0)),"") -> JOHANA LLANCAPICHUN | D33: 08:30 | E33: 18:30 | F33: 14:24 | G33: 15:19 | H33: 6 | I33: 15 | J33: 0 | K33: 0 | L33: 0 | M33: =IF(OR(D33="",E33=""),"",ROUND(((E33-D33)*24)-((G33-F33)*24)-((H33+I33)/60),2)) -> 8.73 | N33: =IF(OR($D33="",$S33=""),"",IFERROR(MAX(0,ROUND(($D33-INDEX(Config!$C$15:$C$18,MATCH($S33,Config!$B$15:$B$18,0)))*24*60,0)),"")) -> 0 | O33: =IF(OR(F33="",G33=""),"",ROUND((G33-F33)*24*60,0)) -> 55 | P33: =IF(O33="","",O33+H33+I33) -> 76 | Q33: =IF(OR($P33="",$S33=""),"",IFERROR($P33-INDEX(Config!$E$15:$E$18,MATCH($S33,Config!$B$15:$B$18,0)),"")) -> 16 | R33: =IF($A33="","",IF($D33="","Ausente",IF($N33="","",IF($N33>0,"Atrasado","Puntual")))) -> Puntual | S33: =IF(OR($A33="",$C33=""),"",IFERROR(INDEX(Turno!$C$3:$V$32,MATCH($C33,Turno!$B$3:$B$32,0),MATCH(DAY($A33),Turno!$C$1:$V$1,0)),"")) -> A | T33: =IF(OR($E33="",$S33=""),"",IFERROR(MAX(0,ROUND((INDEX(Config!$D$15:$D$18,MATCH($S33,Config!$B$15:$B$18,0))-$E33)*1440,0)),"")) -> 0 | U33: =IF(OR($N33="",$T33=""),"",IFERROR(MAX(0,1-($N33+$T33+MAX(0,N($Q33)))/ROUND((INDEX(Config!$D$15:$D$18,MATCH($S33,Config!$B$15:$B$18,0))-INDEX(Config!$C$15:$C$18,MATCH($S33,Config!$B$15:$B$18,0)))*1440,0)),"")) -> 0.97333333
A34: 46239 | B34: 13026344-5 | C34: =IFERROR(INDEX(Ejecutivos!$B$2:$B$100,MATCH(B34,Ejecutivos!$A$2:$A$100,0)),"") -> KATIA HALD | D34: 08:30 | E34: 18:32 | F34: 15:37 | G34: 16:37 | H34: 16 | I34: 15 | J34: 12 | K34: 1 | L34: 0 | M34: =IF(OR(D34="",E34=""),"",ROUND(((E34-D34)*24)-((G34-F34)*24)-((H34+I34)/60),2)) -> 8.52 | N34: =IF(OR($D34="",$S34=""),"",IFERROR(MAX(0,ROUND(($D34-INDEX(Config!$C$15:$C$18,MATCH($S34,Config!$B$15:$B$18,0)))*24*60,0)),"")) -> 0 | O34: =IF(OR(F34="",G34=""),"",ROUND((G34-F34)*24*60,0)) -> 60 | P34: =IF(O34="","",O34+H34+I34) -> 91 | Q34: =IF(OR($P34="",$S34=""),"",IFERROR($P34-INDEX(Config!$E$15:$E$18,MATCH($S34,Config!$B$15:$B$18,0)),"")) -> 31 | R34: =IF($A34="","",IF($D34="","Ausente",IF($N34="","",IF($N34>0,"Atrasado","Puntual")))) -> Puntual | S34: =IF(OR($A34="",$C34=""),"",IFERROR(INDEX(Turno!$C$3:$V$32,MATCH($C34,Turno!$B$3:$B$32,0),MATCH(DAY($A34),Turno!$C$1:$V$1,0)),"")) -> A | T34: =IF(OR($E34="",$S34=""),"",IFERROR(MAX(0,ROUND((INDEX(Config!$D$15:$D$18,MATCH($S34,Config!$B$15:$B$18,0))-$E34)*1440,0)),"")) -> 0 | U34: =IF(OR($N34="",$T34=""),"",IFERROR(MAX(0,1-($N34+$T34+MAX(0,N($Q34)))/ROUND((INDEX(Config!$D$15:$D$18,MATCH($S34,Config!$B$15:$B$18,0))-INDEX(Config!$C$15:$C$18,MATCH($S34,Config!$B$15:$B$18,0)))*1440,0)),"")) -> 0.94833333
A35: 46239 | B35: 13638765-0 | C35: =IFERROR(INDEX(Ejecutivos!$B$2:$B$100,MATCH(B35,Ejecutivos!$A$2:$A$100,0)),"") -> MANUEL MONSALVE | D35: 08:29 | E35: 18:41 | F35: 13:28 | G35: 13:49 | H35: 0 | I35: 0 | J35: 12 | K35: 2 | L35: 0 | M35: =IF(OR(D35="",E35=""),"",ROUND(((E35-D35)*24)-((G35-F35)*24)-((H35+I35)/60),2)) -> 9.85 | N35: =IF(OR($D35="",$S35=""),"",IFERROR(MAX(0,ROUND(($D35-INDEX(Config!$C$15:$C$18,MATCH($S35,Config!$B$15:$B$18,0)))*24*60,0)),"")) -> 0 | O35: =IF(OR(F35="",G35=""),"",ROUND((G35-F35)*24*60,0)) -> 21 | P35: =IF(O35="","",O35+H35+I35) -> 21 | Q35: =IF(OR($P35="",$S35=""),"",IFERROR($P35-INDEX(Config!$E$15:$E$18,MATCH($S35,Config!$B$15:$B$18,0)),"")) -> -39 | R35: =IF($A35="","",IF($D35="","Ausente",IF($N35="","",IF($N35>0,"Atrasado","Puntual")))) -> Puntual | S35: =IF(OR($A35="",$C35=""),"",IFERROR(INDEX(Turno!$C$3:$V$32,MATCH($C35,Turno!$B$3:$B$32,0),MATCH(DAY($A35),Turno!$C$1:$V$1,0)),"")) -> A | T35: =IF(OR($E35="",$S35=""),"",IFERROR(MAX(0,ROUND((INDEX(Config!$D$15:$D$18,MATCH($S35,Config!$B$15:$B$18,0))-$E35)*1440,0)),"")) -> 0 | U35: =IF(OR($N35="",$T35=""),"",IFERROR(MAX(0,1-($N35+$T35+MAX(0,N($Q35)))/ROUND((INDEX(Config!$D$15:$D$18,MATCH($S35,Config!$B$15:$B$18,0))-INDEX(Config!$C$15:$C$18,MATCH($S35,Config!$B$15:$B$18,0)))*1440,0)),"")) -> 1
A36: 46239 | B36: 13337549-K | C36: =IFERROR(INDEX(Ejecutivos!$B$2:$B$100,MATCH(B36,Ejecutivos!$A$2:$A$100,0)),"") -> MANUELA ASTUDILLO | D36: 08:31 | E36: 18:00 | F36: 14:41 | G36: 15:12 | H36: 16 | I36: 15 | J36: 20 | K36: 2 | L36: 0 | M36: =IF(OR(D36="",E36=""),"",ROUND(((E36-D36)*24)-((G36-F36)*24)-((H36+I36)/60),2)) -> 8.45 | N36: =IF(OR($D36="",$S36=""),"",IFERROR(MAX(0,ROUND(($D36-INDEX(Config!$C$15:$C$18,MATCH($S36,Config!$B$15:$B$18,0)))*24*60,0)),"")) -> 1 | O36: =IF(OR(F36="",G36=""),"",ROUND((G36-F36)*24*60,0)) -> 31 | P36: =IF(O36="","",O36+H36+I36) -> 62 | Q36: =IF(OR($P36="",$S36=""),"",IFERROR($P36-INDEX(Config!$E$15:$E$18,MATCH($S36,Config!$B$15:$B$18,0)),"")) -> 2 | R36: =IF($A36="","",IF($D36="","Ausente",IF($N36="","",IF($N36>0,"Atrasado","Puntual")))) -> Atrasado | S36: =IF(OR($A36="",$C36=""),"",IFERROR(INDEX(Turno!$C$3:$V$32,MATCH($C36,Turno!$B$3:$B$32,0),MATCH(DAY($A36),Turno!$C$1:$V$1,0)),"")) -> A | T36: =IF(OR($E36="",$S36=""),"",IFERROR(MAX(0,ROUND((INDEX(Config!$D$15:$D$18,MATCH($S36,Config!$B$15:$B$18,0))-$E36)*1440,0)),"")) -> 30 | U36: =IF(OR($N36="",$T36=""),"",IFERROR(MAX(0,1-($N36+$T36+MAX(0,N($Q36)))/ROUND((INDEX(Config!$D$15:$D$18,MATCH($S36,Config!$B$15:$B$18,0))-INDEX(Config!$C$15:$C$18,MATCH($S36,Config!$B$15:$B$18,0)))*1440,0)),"")) -> 0.945
A37: 46239 | B37: 18123009-6 | C37: =IFERROR(INDEX(Ejecutivos!$B$2:$B$100,MATCH(B37,Ejecutivos!$A$2:$A$100,0)),"") -> MAXIMILIANO OLIVARES | D37: 08:30 | E37: 18:30 | F37: 12:09 | G37: 13:09 | H37: 15 | I37: 15 | J37: 11 | K37: 4 | L37: 0 | M37: =IF(OR(D37="",E37=""),"",ROUND(((E37-D37)*24)-((G37-F37)*24)-((H37+I37)/60),2)) -> 8.5 | N37: =IF(OR($D37="",$S37=""),"",IFERROR(MAX(0,ROUND(($D37-INDEX(Config!$C$15:$C$18,MATCH($S37,Config!$B$15:$B$18,0)))*24*60,0)),"")) -> 0 | O37: =IF(OR(F37="",G37=""),"",ROUND((G37-F37)*24*60,0)) -> 60 | P37: =IF(O37="","",O37+H37+I37) -> 90 | Q37: =IF(OR($P37="",$S37=""),"",IFERROR($P37-INDEX(Config!$E$15:$E$18,MATCH($S37,Config!$B$15:$B$18,0)),"")) -> 30 | R37: =IF($A37="","",IF($D37="","Ausente",IF($N37="","",IF($N37>0,"Atrasado","Puntual")))) -> Puntual | S37: =IF(OR($A37="",$C37=""),"",IFERROR(INDEX(Turno!$C$3:$V$32,MATCH($C37,Turno!$B$3:$B$32,0),MATCH(DAY($A37),Turno!$C$1:$V$1,0)),"")) -> A | T37: =IF(OR($E37="",$S37=""),"",IFERROR(MAX(0,ROUND((INDEX(Config!$D$15:$D$18,MATCH($S37,Config!$B$15:$B$18,0))-$E37)*1440,0)),"")) -> 0 | U37: =IF(OR($N37="",$T37=""),"",IFERROR(MAX(0,1-($N37+$T37+MAX(0,N($Q37)))/ROUND((INDEX(Config!$D$15:$D$18,MATCH($S37,Config!$B$15:$B$18,0))-INDEX(Config!$C$15:$C$18,MATCH($S37,Config!$B$15:$B$18,0)))*1440,0)),"")) -> 0.95
A38: 46239 | B38: 19421111-2 | C38: =IFERROR(INDEX(Ejecutivos!$B$2:$B$100,MATCH(B38,Ejecutivos!$A$2:$A$100,0)),"") -> MELISSA SALGADO | D38: 08:30 | E38: 16:02 | F38: 12:42 | G38: 13:12 | H38: 15 | I38: 15 | J38: 19 | K38: 2 | L38: 0 | M38: =IF(OR(D38="",E38=""),"",ROUND(((E38-D38)*24)-((G38-F38)*24)-((H38+I38)/60),2)) -> 6.53 | N38: =IF(OR($D38="",$S38=""),"",IFERROR(MAX(0,ROUND(($D38-INDEX(Config!$C$15:$C$18,MATCH($S38,Config!$B$15:$B$18,0)))*24*60,0)),"")) -> 0 | O38: =IF(OR(F38="",G38=""),"",ROUND((G38-F38)*24*60,0)) -> 30 | P38: =IF(O38="","",O38+H38+I38) -> 60 | Q38: =IF(OR($P38="",$S38=""),"",IFERROR($P38-INDEX(Config!$E$15:$E$18,MATCH($S38,Config!$B$15:$B$18,0)),"")) -> 0 | R38: =IF($A38="","",IF($D38="","Ausente",IF($N38="","",IF($N38>0,"Atrasado","Puntual")))) -> Puntual | S38: =IF(OR($A38="",$C38=""),"",IFERROR(INDEX(Turno!$C$3:$V$32,MATCH($C38,Turno!$B$3:$B$32,0),MATCH(DAY($A38),Turno!$C$1:$V$1,0)),"")) -> A | T38: =IF(OR($E38="",$S38=""),"",IFERROR(MAX(0,ROUND((INDEX(Config!$D$15:$D$18,MATCH($S38,Config!$B$15:$B$18,0))-$E38)*1440,0)),"")) -> 148 | U38: =IF(OR($N38="",$T38=""),"",IFERROR(MAX(0,1-($N38+$T38+MAX(0,N($Q38)))/ROUND((INDEX(Config!$D$15:$D$18,MATCH($S38,Config!$B$15:$B$18,0))-INDEX(Config!$C$15:$C$18,MATCH($S38,Config!$B$15:$B$18,0)))*1440,0)),"")) -> 0.75333333
A39: 46239 | B39: 27105214-6 | C39: =IFERROR(INDEX(Ejecutivos!$B$2:$B$100,MATCH(B39,Ejecutivos!$A$2:$A$100,0)),"") -> NANCI MENDEZ | D39: 08:31 | E39: 16:31 | F39: 12:32 | G39: 13:33 | H39: 17 | I39: 16 | J39: 0 | K39: 0 | L39: 0 | M39: =IF(OR(D39="",E39=""),"",ROUND(((E39-D39)*24)-((G39-F39)*24)-((H39+I39)/60),2)) -> 6.43 | N39: =IF(OR($D39="",$S39=""),"",IFERROR(MAX(0,ROUND(($D39-INDEX(Config!$C$15:$C$18,MATCH($S39,Config!$B$15:$B$18,0)))*24*60,0)),"")) -> 1 | O39: =IF(OR(F39="",G39=""),"",ROUND((G39-F39)*24*60,0)) -> 61 | P39: =IF(O39="","",O39+H39+I39) -> 94 | Q39: =IF(OR($P39="",$S39=""),"",IFERROR($P39-INDEX(Config!$E$15:$E$18,MATCH($S39,Config!$B$15:$B$18,0)),"")) -> 34 | R39: =IF($A39="","",IF($D39="","Ausente",IF($N39="","",IF($N39>0,"Atrasado","Puntual")))) -> Atrasado | S39: =IF(OR($A39="",$C39=""),"",IFERROR(INDEX(Turno!$C$3:$V$32,MATCH($C39,Turno!$B$3:$B$32,0),MATCH(DAY($A39),Turno!$C$1:$V$1,0)),"")) -> C | T39: =IF(OR($E39="",$S39=""),"",IFERROR(MAX(0,ROUND((INDEX(Config!$D$15:$D$18,MATCH($S39,Config!$B$15:$B$18,0))-$E39)*1440,0)),"")) -> 0 | U39: =IF(OR($N39="",$T39=""),"",IFERROR(MAX(0,1-($N39+$T39+MAX(0,N($Q39)))/ROUND((INDEX(Config!$D$15:$D$18,MATCH($S39,Config!$B$15:$B$18,0))-INDEX(Config!$C$15:$C$18,MATCH($S39,Config!$B$15:$B$18,0)))*1440,0)),"")) -> 0.92708333
A40: 46239 | B40: 20828148-8 | C40: =IFERROR(INDEX(Ejecutivos!$B$2:$B$100,MATCH(B40,Ejecutivos!$A$2:$A$100,0)),"") -> TOMAS MAULEN | D40: 08:39 | E40: 22:30 | F40: 15:00 | G40: 15:32 | H40: 16 | I40: 16 | J40: 46 | K40: 15 | L40: 0 | M40: =IF(OR(D40="",E40=""),"",ROUND(((E40-D40)*24)-((G40-F40)*24)-((H40+I40)/60),2)) -> 12.78 | N40: =IF(OR($D40="",$S40=""),"",IFERROR(MAX(0,ROUND(($D40-INDEX(Config!$C$15:$C$18,MATCH($S40,Config!$B$15:$B$18,0)))*24*60,0)),"")) -> 9 | O40: =IF(OR(F40="",G40=""),"",ROUND((G40-F40)*24*60,0)) -> 32 | P40: =IF(O40="","",O40+H40+I40) -> 64 | Q40: =IF(OR($P40="",$S40=""),"",IFERROR($P40-INDEX(Config!$E$15:$E$18,MATCH($S40,Config!$B$15:$B$18,0)),"")) -> 4 | R40: =IF($A40="","",IF($D40="","Ausente",IF($N40="","",IF($N40>0,"Atrasado","Puntual")))) -> Atrasado | S40: =IF(OR($A40="",$C40=""),"",IFERROR(INDEX(Turno!$C$3:$V$32,MATCH($C40,Turno!$B$3:$B$32,0),MATCH(DAY($A40),Turno!$C$1:$V$1,0)),"")) -> C | T40: =IF(OR($E40="",$S40=""),"",IFERROR(MAX(0,ROUND((INDEX(Config!$D$15:$D$18,MATCH($S40,Config!$B$15:$B$18,0))-$E40)*1440,0)),"")) -> 0 | U40: =IF(OR($N40="",$T40=""),"",IFERROR(MAX(0,1-($N40+$T40+MAX(0,N($Q40)))/ROUND((INDEX(Config!$D$15:$D$18,MATCH($S40,Config!$B$15:$B$18,0))-INDEX(Config!$C$15:$C$18,MATCH($S40,Config!$B$15:$B$18,0)))*1440,0)),"")) -> 0.97291667
A41: 06-08-2026 | B41: 26612947-5 | C41: =IFERROR(INDEX(Ejecutivos!$B$2:$B$100,MATCH(B41,Ejecutivos!$A$2:$A$100,0)),"") -> ALEJANDRA CHACON | D41: 08:36 | E41: 17:03 | F41: 14:00 | G41: 14:31 | H41: 16 | I41: 16 | J41: 15 | K41: 2 | L41: 0 | M41: =IF(OR(D41="",E41=""),"",ROUND(((E41-D41)*24)-((G41-F41)*24)-((H41+I41)/60),2)) -> 7.4 | N41: =IF(OR($D41="",$S41=""),"",IFERROR(MAX(0,ROUND(($D41-INDEX(Config!$C$15:$C$18,MATCH($S41,Config!$B$15:$B$18,0)))*24*60,0)),"")) -> 6 | O41: =IF(OR(F41="",G41=""),"",ROUND((G41-F41)*24*60,0)) -> 31 | P41: =IF(O41="","",O41+H41+I41) -> 63 | Q41: =IF(OR($P41="",$S41=""),"",IFERROR($P41-INDEX(Config!$E$15:$E$18,MATCH($S41,Config!$B$15:$B$18,0)),"")) -> 3 | R41: =IF($A41="","",IF($D41="","Ausente",IF($N41="","",IF($N41>0,"Atrasado","Puntual")))) -> Atrasado | S41: =IF(OR($A41="",$C41=""),"",IFERROR(INDEX(Turno!$C$3:$V$32,MATCH($C41,Turno!$B$3:$B$32,0),MATCH(DAY($A41),Turno!$C$1:$V$1,0)),"")) -> B | T41: =IF(OR($E41="",$S41=""),"",IFERROR(MAX(0,ROUND((INDEX(Config!$D$15:$D$18,MATCH($S41,Config!$B$15:$B$18,0))-$E41)*1440,0)),"")) -> 27 | U41: =IF(OR($N41="",$T41=""),"",IFERROR(MAX(0,1-($N41+$T41+MAX(0,N($Q41)))/ROUND((INDEX(Config!$D$15:$D$18,MATCH($S41,Config!$B$15:$B$18,0))-INDEX(Config!$C$15:$C$18,MATCH($S41,Config!$B$15:$B$18,0)))*1440,0)),"")) -> 0.93333333
A42: 06-08-2026 | B42: 13093458-7 | C42: =IFERROR(INDEX(Ejecutivos!$B$2:$B$100,MATCH(B42,Ejecutivos!$A$2:$A$100,0)),"") -> ALEJANDRA ORELLANA | D42: 08:30 | E42: 18:34 | F42: 12:09 | G42: 13:09 | H42: 15 | I42: 16 | J42: 4 | K42: 1 | L42: 0 | M42: =IF(OR(D42="",E42=""),"",ROUND(((E42-D42)*24)-((G42-F42)*24)-((H42+I42)/60),2)) -> 8.55 | N42: =IF(OR($D42="",$S42=""),"",IFERROR(MAX(0,ROUND(($D42-INDEX(Config!$C$15:$C$18,MATCH($S42,Config!$B$15:$B$18,0)))*24*60,0)),"")) -> 0 | O42: =IF(OR(F42="",G42=""),"",ROUND((G42-F42)*24*60,0)) -> 60 | P42: =IF(O42="","",O42+H42+I42) -> 91 | Q42: =IF(OR($P42="",$S42=""),"",IFERROR($P42-INDEX(Config!$E$15:$E$18,MATCH($S42,Config!$B$15:$B$18,0)),"")) -> 31 | R42: =IF($A42="","",IF($D42="","Ausente",IF($N42="","",IF($N42>0,"Atrasado","Puntual")))) -> Puntual | S42: =IF(OR($A42="",$C42=""),"",IFERROR(INDEX(Turno!$C$3:$V$32,MATCH($C42,Turno!$B$3:$B$32,0),MATCH(DAY($A42),Turno!$C$1:$V$1,0)),"")) -> A | T42: =IF(OR($E42="",$S42=""),"",IFERROR(MAX(0,ROUND((INDEX(Config!$D$15:$D$18,MATCH($S42,Config!$B$15:$B$18,0))-$E42)*1440,0)),"")) -> 0 | U42: =IF(OR($N42="",$T42=""),"",IFERROR(MAX(0,1-($N42+$T42+MAX(0,N($Q42)))/ROUND((INDEX(Config!$D$15:$D$18,MATCH($S42,Config!$B$15:$B$18,0))-INDEX(Config!$C$15:$C$18,MATCH($S42,Config!$B$15:$B$18,0)))*1440,0)),"")) -> 0.94833333
...

Sheet KPI_Mensual
A1: Rut | B1: Nombre | C1: Llamadas | D1: Saliente | E1: TMO (seg) | F1: Disponibilidad | G1: Adherencia | H1: Ocupación | I1: Transferencias | J1: Cumplimiento meta | K1: Supervisor | L1: % Contactabilidad Out | M1: Tipificaciones
